Workbook

Sheet knn_filter_data
A1: chemical formula | B1: element1 | C1: element1 numbers | D1: element2 | E1: element2 numbers | F1: element3 | G1: element3 numbers | H1: element4 | I1: element4 numbers | J1: elements | K1: doping1 numbers | L1: doping element2 | M1: doping2 numbers | N1: doping element3 | O1: doping3 numbers | P1: Nb1 | Q1: Nb2 | R1: Nb3 | S1: Nb4 | T1: Nb5 | U1: Nb6 | V1: Nb7 | W1: Nb8 | X1: Nb9 | Y1: Nb10 | Z1: Nb11 | AA1: Nb12 | AB1: Nb13 | AC1: Nb14 | AD1: Nb15 | AE1: Nb16 | AF1: Nb17 | AG1: Nb18 | AH1: Nb19 | AI1: Nb20 | AJ1: Nb21 | AK1: Nb22 | AL1: Nb23 | AM1: Nb24 | AN1: Nb25 | AO1: Nb26 | AP1: Nb27 | AQ1: Nb28 | AR1: O1 | AS1: O2 | AT1: O3 | AU1: O4 | AV1: O5 | AW1: O6 | AX1: O7 | AY1: O8 | AZ1: O9 | BA1: O10 | BB1: O11 | BC1: O12 | BD1: O13 | BE1: O14 | BF1: O15 | BG1: O16 | BH1: O17 | BI1: O18 | BJ1: O19 | BK1: O20 | BL1: O21 | BM1: O22 | BN1: O23 | BO1: O24 | BP1: O25 | BQ1: O26 | BR1: O27 | BS1: O28 | BT1: K1 | BU1: K2 | BV1: K3 | BW1: K4 | BX1: K5 | BY1: K6 | BZ1: K7 | CA1: K8 | CB1: K9 | CC1: K10 | CD1: K11 | CE1: K12 | CF1: K13 | CG1: K14 | CH1: K15 | CI1: K16 | CJ1: K17 | CK1: K18 | CL1: K19 | CM1: K20 | CN1: K21 | CO1: K22 | CP1: K23 | CQ1: K24 | CR1: K25 | CS1: K26 | CT1: K27 | CU1: K28 | CV1: Na1 | CW1: Na2 | CX1: Na3 | CY1: Na4 | CZ1: Na5 | DA1: Na6 | DB1: Na7 | DC1: Na8 | DD1: Na9 | DE1: Na10 | DF1: Na11 | DG1: Na12 | DH1: Na13 | DI1: Na14 | DJ1: Na15 | DK1: Na16 | DL1: Na17 | DM1: Na18 | DN1: Na19 | DO1: Na20 | DP1: Na21 | DQ1: Na22 | DR1: Na23 | DS1: Na24 | DT1: Na25 | DU1: Na26 | DV1: Na27 | DW1: Na28 | DX1: Atomic electron scattering factor at 0.5 | DY1: Atomic environment number (Villars, Daams) | DZ1: Boiling temperature | EA1: Compression modulus | EB1: Density | EC1: Distance from core electron (Schubert) | ED1: Distance from valence electron (Schubert) | EE1: Electrochemical weight equivalent | EF1: Electronegativity (Alfred-Rochow) | EG1: Electronegativity (Martynov&Batsanov) | EH1: Electronegativity absolute | EI1: Energy of ionization second | EJ1: Energy of ionization third | EK1: Enthalpy of melting | EL1: Entropy of solid | EM1: Group number | EN1: Magnetic frequency of nuclei | EO1: Mendeleev chemists sequence | EP1: Mendeleev d-t start left | EQ1: Molar heat capacity | ER1: Moment nuclear magnetic | ES1: Oxidation state first | ET1: Radii covalent | EU1: Radii metal (Waber) | EV1: Spectral lines no | EW1: Spin nuclei | EX1: Thermal neutron capture cross section | EY1: Volume of atom (Villars, Daams) | EZ1: Eformation | FB1: EF | FC1: HF | FD1: E-TOT | FE1: E_atom | FF1: E_atom | FG1: a0 | FH1: b0 | FI1: c0 | FJ1: volume | FK1: volume_atom | FL1: EF-V | FM1: HF-V | FN1: VBM | FO1: CBM | FQ1: bandgap | FR1: v_bandgap | FS1: change_bandgap
A2: K23 Ba1 Na24 Nb48 O144 | B2: Nb | C2: 48 | D2: O | E2: 144 | F2: K | G2: 23 | H2: Na | I2: 24 | J2: Ba | K2: 1 | M2: =C2+E2+G2+I2+K2 -> 240 | P2: 1.92 | Q2: 14 | R2: 3573 | S2: 1.702 | T2: 8570 | U2: 0.95 | V2: 1.75 | W2: 0.19256 | X2: 1.23 | Y2: 2.03 | Z2: 4 | AA2: 1382 | AB2: 2416 | AC2: 26.8 | AD2: 36.28 | AE2: 5 | AF2: 24.442 | AG2: 58 | AH2: 50 | AI2: 24.48 | AJ2: 6.144 | AK2: 3 | AL2: 134 | AM2: 1.468 | AN2: 450 | AO2: 4.5 | AP2: 1.15 | AQ2: 1.807 | AR2: 0.232 | AS2: 1 | AT2: 90.19 | AU2: 0.011 | AV2: 2000 | AW2: 0.85 | AX2: 1.2 | AY2: 0.82902 | AZ2: 3.5 | BA2: 3.32 | BB2: 7.54 | BC2: 3388 | BD2: 5300 | BE2: 0.444 | BF2: 205.19507 | BG2: 6 | BH2: 13.557 | BI2: 103 | BJ2: 92 | BK2: 29.355 | BL2: -1.893 | BM2: -2 | BN2: 66 | BO2: 0.89 | BP2: 192 | BQ2: 2.5 | BR2: 0.0028 | BS2: 1.736 | BT2: 0.43 | BU2: 14 | BV2: 1032 | BW2: 0.032 | BX2: 862 | BY2: 1.32 | BZ2: 4.6 | CA2: 0.40514 | CB2: 0.91 | CC2: 0.8 | CD2: 2.42 | CE2: 3051 | CF2: 4411 | CG2: 2.39 | CH2: 64.43485 | CI2: 1 | CJ2: 4.667 | CK2: 6 | CL2: 4 | CM2: 29.58 | CN2: 0.391 | CO2: 1 | CP2: 203 | CQ2: 2.376 | CR2: 87 | CS2: 1.5 | CT2: 2.1 | CU2: 7.572 | CV2: 0.278 | CW2: 14 | CX2: 1153 | CY2: 0.068 | CZ2: 971 | DA2: 1.07 | DB2: 3.73 | DC2: 0.23831 | DD2: 1.01 | DE2: 0.89 | DF2: 2.85 | DG2: 4562 | DH2: 6912 | DI2: 2.64 | DJ2: 51.12083 | DK2: 1 | DL2: 26.451 | DM2: 7 | DN2: 5 | DO2: 28.24 | DP2: 2.216 | DQ2: 1 | DR2: 154 | DS2: 1.911 | DT2: 83 | DU2: 1.5 | DV2: 0.53 | DW2: 3.926 | DX2: 2.45 | DY2: 14 | DZ2: 1910 | EA2: 0.103 | EB2: 3594 | EC2: 1.44 | ED2: 3.35 | EE2: 0.71171 | EF2: 0.97 | EG2: 1.08 | EH2: 2.4 | EI2: 965 | EJ2: 3546 | EK2: 7.8 | EL2: 64.8954 | EM2: 2 | EN2: 11.113 | EO2: 10 | EP2: 9 | EQ2: 28.07 | ER2: 0.931 | ES2: 2 | ET2: 198 | EU2: 2.243 | EV2: 223 | EW2: 1.5 | EX2: 1.3 | EY2: 6.299 | EZ2: -1.0768843 | FB2: =EZ2 -> -1.0768843 | FC2: =EZ6 -> 1.0694747 | FD2: -1835.858 | FE2: =FD2/M2 -> -7.6494085 | FF2: =FE2*1000 -> -7649.4085 | FG2: 4.03059 | FH2: 4.0303725 | FI2: 4.1211667 | FJ2: 66.94745 | FK2: =FJ2/M2 -> 0.27894771 | FL2: =FJ2 -> 66.94745 | FM2: =FJ6 -> 66.221554 | FN2: -0.85 | FO2: 1.93 | FP2: 2.78 | FQ2: =FP2+0.01 -> 2.79 | FR2: =FQ2-2.86 -> -0.07 | FS2: =IF(FR2<0,0,1) -> 0
A3: K24 Ba1 Na23 Nb48 O144 | B3: Nb | C3: 48 | D3: O | E3: 144 | F3: K | G3: 24 | H3: Na | I3: 23 | J3: Ba | K3: 1 | M3: =C3+E3+G3+I3+K3 -> 240 | P3: 1.92 | Q3: 14 | R3: 3573 | S3: 1.702 | T3: 8570 | U3: 0.95 | V3: 1.75 | W3: 0.19256 | X3: 1.23 | Y3: 2.03 | Z3: 4 | AA3: 1382 | AB3: 2416 | AC3: 26.8 | AD3: 36.28 | AE3: 5 | AF3: 24.442 | AG3: 58 | AH3: 50 | AI3: 24.48 | AJ3: 6.144 | AK3: 3 | AL3: 134 | AM3: 1.468 | AN3: 450 | AO3: 4.5 | AP3: 1.15 | AQ3: 1.807 | AR3: 0.232 | AS3: 1 | AT3: 90.19 | AU3: 0.011 | AV3: 2000 | AW3: 0.85 | AX3: 1.2 | AY3: 0.82902 | AZ3: 3.5 | BA3: 3.32 | BB3: 7.54 | BC3: 3388 | BD3: 5300 | BE3: 0.444 | BF3: 205.19507 | BG3: 6 | BH3: 13.557 | BI3: 103 | BJ3: 92 | BK3: 29.355 | BL3: -1.893 | BM3: -2 | BN3: 66 | BO3: 0.89 | BP3: 192 | BQ3: 2.5 | BR3: 0.0028 | BS3: 1.736 | BT3: 0.43 | BU3: 14 | BV3: 1032 | BW3: 0.032 | BX3: 862 | BY3: 1.32 | BZ3: 4.6 | CA3: 0.40514 | CB3: 0.91 | CC3: 0.8 | CD3: 2.42 | CE3: 3051 | CF3: 4411 | CG3: 2.39 | CH3: 64.43485 | CI3: 1 | CJ3: 4.667 | CK3: 6 | CL3: 4 | CM3: 29.58 | CN3: 0.391 | CO3: 1 | CP3: 203 | CQ3: 2.376 | CR3: 87 | CS3: 1.5 | CT3: 2.1 | CU3: 7.572 | CV3: 0.278 | CW3: 14 | CX3: 1153 | CY3: 0.068 | CZ3: 971 | DA3: 1.07 | DB3: 3.73 | DC3: 0.23831 | DD3: 1.01 | DE3: 0.89 | DF3: 2.85 | DG3: 4562 | DH3: 6912 | DI3: 2.64 | DJ3: 51.12083 | DK3: 1 | DL3: 26.451 | DM3: 7 | DN3: 5 | DO3: 28.24 | DP3: 2.216 | DQ3: 1 | DR3: 154 | DS3: 1.911 | DT3: 83 | DU3: 1.5 | DV3: 0.53 | DW3: 3.926 | DX3: 2.45 | DY3: 14 | DZ3: 1910 | EA3: 0.103 | EB3: 3594 | EC3: 1.44 | ED3: 3.35 | EE3: 0.71171 | EF3: 0.97 | EG3: 1.08 | EH3: 2.4 | EI3: 965 | EJ3: 3546 | EK3: 7.8 | EL3: 64.8954 | EM3: 2 | EN3: 11.113 | EO3: 10 | EP3: 9 | EQ3: 28.07 | ER3: 0.931 | ES3: 2 | ET3: 198 | EU3: 2.243 | EV3: 223 | EW3: 1.5 | EX3: 1.3 | EY3: 6.299 | EZ3: -1.3996695 | FB3: =EZ3 -> -1.3996695 | FC3: =EZ7 -> 1.1549066 | FD3: -1835.8966 | FE3: =FD3/M3 -> -7.6495692 | FF3: =FE3*1000 -> -7649.5692 | FG3: 4.0310275 | FH3: 4.03064 | FI3: 4.1209 | FJ3: 66.954802 | FK3: =FJ3/M3 -> 0.27897834 | FL3: =FJ3 -> 66.954802 | FM3: =FJ7 -> 66.309207 | FN3: -0.96 | FO3: 1.97 | FP3: 2.93 | FQ3: =FP3+0.01 -> 2.94 | FR3: =FQ3-2.86 -> 0.08 | FS3: =IF(FR3<0,0,1) -> 1
A4: K24 Ba1 Na24 Nb47 O144 | B4: Nb | C4: 47 | D4: O | E4: 144 | F4: K | G4: 24 | H4: Na | I4: 24 | J4: Ba | K4: 1 | M4: =C4+E4+G4+I4+K4 -> 240 | P4: 1.92 | Q4: 14 | R4: 3573 | S4: 1.702 | T4: 8570 | U4: 0.95 | V4: 1.75 | W4: 0.19256 | X4: 1.23 | Y4: 2.03 | Z4: 4 | AA4: 1382 | AB4: 2416 | AC4: 26.8 | AD4: 36.28 | AE4: 5 | AF4: 24.442 | AG4: 58 | AH4: 50 | AI4: 24.48 | AJ4: 6.144 | AK4: 3 | AL4: 134 | AM4: 1.468 | AN4: 450 | AO4: 4.5 | AP4: 1.15 | AQ4: 1.807 | AR4: 0.232 | AS4: 1 | AT4: 90.19 | AU4: 0.011 | AV4: 2000 | AW4: 0.85 | AX4: 1.2 | AY4: 0.82902 | AZ4: 3.5 | BA4: 3.32 | BB4: 7.54 | BC4: 3388 | BD4: 5300 | BE4: 0.444 | BF4: 205.19507 | BG4: 6 | BH4: 13.557 | BI4: 103 | BJ4: 92 | BK4: 29.355 | BL4: -1.893 | BM4: -2 | BN4: 66 | BO4: 0.89 | BP4: 192 | BQ4: 2.5 | BR4: 0.0028 | BS4: 1.736 | BT4: 0.43 | BU4: 14 | BV4: 1032 | BW4: 0.032 | BX4: 862 | BY4: 1.32 | BZ4: 4.6 | CA4: 0.40514 | CB4: 0.91 | CC4: 0.8 | CD4: 2.42 | CE4: 3051 | CF4: 4411 | CG4: 2.39 | CH4: 64.43485 | CI4: 1 | CJ4: 4.667 | CK4: 6 | CL4: 4 | CM4: 29.58 | CN4: 0.391 | CO4: 1 | CP4: 203 | CQ4: 2.376 | CR4: 87 | CS4: 1.5 | CT4: 2.1 | CU4: 7.572 | CV4: 0.278 | CW4: 14 | CX4: 1153 | CY4: 0.068 | CZ4: 971 | DA4: 1.07 | DB4: 3.73 | DC4: 0.23831 | DD4: 1.01 | DE4: 0.89 | DF4: 2.85 | DG4: 4562 | DH4: 6912 | DI4: 2.64 | DJ4: 51.12083 | DK4: 1 | DL4: 26.451 | DM4: 7 | DN4: 5 | DO4: 28.24 | DP4: 2.216 | DQ4: 1 | DR4: 154 | DS4: 1.911 | DT4: 83 | DU4: 1.5 | DV4: 0.53 | DW4: 3.926 | DX4: 2.45 | DY4: 14 | DZ4: 1910 | EA4: 0.103 | EB4: 3594 | EC4: 1.44 | ED4: 3.35 | EE4: 0.71171 | EF4: 0.97 | EG4: 1.08 | EH4: 2.4 | EI4: 965 | EJ4: 3546 | EK4: 7.8 | EL4: 64.8954 | EM4: 2 | EN4: 11.113 | EO4: 10 | EP4: 9 | EQ4: 28.07 | ER4: 0.931 | ES4: 2 | ET4: 198 | EU4: 2.243 | EV4: 223 | EW4: 1.5 | EX4: 1.3 | EY4: 6.299 | EZ4: 12.475395 | FB4: =EZ4 -> 12.475395 | FC4: =EZ8 -> 13.970723 | FD4: -1813.24 | FE4: =FD4/M4 -> -7.5551665 | FF4: =FE4*1000 -> -7555.1665 | FG4: 4.03212 | FH4: 4.0311075 | FI4: 4.1226867 | FJ4: 67.009817 | FK4: =FJ4/M4 -> 0.27920757 | FL4: =FJ4 -> 67.009817 | FM4: =FJ8 -> 66.440508 | FN4: -0.9 | FO4: 1.96 | FP4: 2.86 | FQ4: =FP4+0.01 -> 2.87 | FR4: =FQ4-2.86 -> 0.01 | FS4: =IF(FR4<0,0,1) -> 1
A5: K24 Ba1 Na24 Nb48 O143 | B5: Nb | C5: 48 | D5: O | E5: 143 | F5: K | G5: 24 | H5: Na | I5: 24 | J5: Ba | K5: 1 | M5: =C5+E5+G5+I5+K5 -> 240 | P5: 1.92 | Q5: 14 | R5: 3573 | S5: 1.702 | T5: 8570 | U5: 0.95 | V5: 1.75 | W5: 0.19256 | X5: 1.23 | Y5: 2.03 | Z5: 4 | AA5: 1382 | AB5: 2416 | AC5: 26.8 | AD5: 36.28 | AE5: 5 | AF5: 24.442 | AG5: 58 | AH5: 50 | AI5: 24.48 | AJ5: 6.144 | AK5: 3 | AL5: 134 | AM5: 1.468 | AN5: 450 | AO5: 4.5 | AP5: 1.15 | AQ5: 1.807 | AR5: 0.232 | AS5: 1 | AT5: 90.19 | AU5: 0.011 | AV5: 2000 | AW5: 0.85 | AX5: 1.2 | AY5: 0.82902 | AZ5: 3.5 | BA5: 3.32 | BB5: 7.54 | BC5: 3388 | BD5: 5300 | BE5: 0.444 | BF5: 205.19507 | BG5: 6 | BH5: 13.557 | BI5: 103 | BJ5: 92 | BK5: 29.355 | BL5: -1.893 | BM5: -2 | BN5: 66 | BO5: 0.89 | BP5: 192 | BQ5: 2.5 | BR5: 0.0028 | BS5: 1.736 | BT5: 0.43 | BU5: 14 | BV5: 1032 | BW5: 0.032 | BX5: 862 | BY5: 1.32 | BZ5: 4.6 | CA5: 0.40514 | CB5: 0.91 | CC5: 0.8 | CD5: 2.42 | CE5: 3051 | CF5: 4411 | CG5: 2.39 | CH5: 64.43485 | CI5: 1 | CJ5: 4.667 | CK5: 6 | CL5: 4 | CM5: 29.58 | CN5: 0.391 | CO5: 1 | CP5: 203 | CQ5: 2.376 | CR5: 87 | CS5: 1.5 | CT5: 2.1 | CU5: 7.572 | CV5: 0.278 | CW5: 14 | CX5: 1153 | CY5: 0.068 | CZ5: 971 | DA5: 1.07 | DB5: 3.73 | DC5: 0.23831 | DD5: 1.01 | DE5: 0.89 | DF5: 2.85 | DG5: 4562 | DH5: 6912 | DI5: 2.64 | DJ5: 51.12083 | DK5: 1 | DL5: 26.451 | DM5: 7 | DN5: 5 | DO5: 28.24 | DP5: 2.216 | DQ5: 1 | DR5: 154 | DS5: 1.911 | DT5: 83 | DU5: 1.5 | DV5: 0.53 | DW5: 3.926 | DX5: 2.45 | DY5: 14 | DZ5: 1910 | EA5: 0.103 | EB5: 3594 | EC5: 1.44 | ED5: 3.35 | EE5: 0.71171 | EF5: 0.97 | EG5: 1.08 | EH5: 2.4 | EI5: 965 | EJ5: 3546 | EK5: 7.8 | EL5: 64.8954 | EM5: 2 | EN5: 11.113 | EO5: 10 | EP5: 9 | EQ5: 28.07 | ER5: 0.931 | ES5: 2 | ET5: 198 | EU5: 2.243 | EV5: 223 | EW5: 1.5 | EX5: 1.3 | EY5: 6.299 | EZ5: 6.4532746 | FB5: =EZ5 -> 6.4532746 | FC5: =EZ9 -> 5.6869536 | FD5: -1824.4065 | FE5: =FD5/M5 -> -7.6016937 | FF5: =FE5*1000 -> -7601.6937 | FG5: 4.035035 | FH5: 4.0340725 | FI5: 4.1188833 | FJ5: 67.045645 | FK5: =FJ5/M5 -> 0.27935685 | FL5: =FJ5 -> 67.045645 | FM5: =FJ9 -> 66.347985 | FN5: -0.97 | FO5: 2.11 | FP5: 3.08 | FQ5: =FP5+0.01 -> 3.09 | FR5: =FQ5-2.86 -> 0.23 | FS5: =IF(FR5<0,0,1) -> 1
A6: K22 Ba1 Na24 Nb48 O144 | B6: Nb | C6: 48 | D6: O | E6: 144 | F6: K | G6: 22 | H6: Na | I6: 24 | J6: Ba | K6: 1 | M6: =C6+E6+G6+I6+K6 -> 239 | P6: 1.92 | Q6: 14 | R6: 3573 | S6: 1.702 | T6: 8570 | U6: 0.95 | V6: 1.75 | W6: 0.19256 | X6: 1.23 | Y6: 2.03 | Z6: 4 | AA6: 1382 | AB6: 2416 | AC6: 26.8 | AD6: 36.28 | AE6: 5 | AF6: 24.442 | AG6: 58 | AH6: 50 | AI6: 24.48 | AJ6: 6.144 | AK6: 3 | AL6: 134 | AM6: 1.468 | AN6: 450 | AO6: 4.5 | AP6: 1.15 | AQ6: 1.807 | AR6: 0.232 | AS6: 1 | AT6: 90.19 | AU6: 0.011 | AV6: 2000 | AW6: 0.85 | AX6: 1.2 | AY6: 0.82902 | AZ6: 3.5 | BA6: 3.32 | BB6: 7.54 | BC6: 3388 | BD6: 5300 | BE6: 0.444 | BF6: 205.19507 | BG6: 6 | BH6: 13.557 | BI6: 103 | BJ6: 92 | BK6: 29.355 | BL6: -1.893 | BM6: -2 | BN6: 66 | BO6: 0.89 | BP6: 192 | BQ6: 2.5 | BR6: 0.0028 | BS6: 1.736 | BT6: 0.43 | BU6: 14 | BV6: 1032 | BW6: 0.032 | BX6: 862 | BY6: 1.32 | BZ6: 4.6 | CA6: 0.40514 | CB6: 0.91 | CC6: 0.8 | CD6: 2.42 | CE6: 3051 | CF6: 4411 | CG6: 2.39 | CH6: 64.43485 | CI6: 1 | CJ6: 4.667 | CK6: 6 | CL6: 4 | CM6: 29.58 | CN6: 0.391 | CO6: 1 | CP6: 203 | CQ6: 2.376 | CR6: 87 | CS6: 1.5 | CT6: 2.1 | CU6: 7.572 | CV6: 0.278 | CW6: 14 | CX6: 1153 | CY6: 0.068 | CZ6: 971 | DA6: 1.07 | DB6: 3.73 | DC6: 0.23831 | DD6: 1.01 | DE6: 0.89 | DF6: 2.85 | DG6: 4562 | DH6: 6912 | DI6: 2.64 | DJ6: 51.12083 | DK6: 1 | DL6: 26.451 | DM6: 7 | DN6: 5 | DO6: 28.24 | DP6: 2.216 | DQ6: 1 | DR6: 154 | DS6: 1.911 | DT6: 83 | DU6: 1.5 | DV6: 0.53 | DW6: 3.926 | DX6: 2.45 | DY6: 14 | DZ6: 1910 | EA6: 0.103 | EB6: 3594 | EC6: 1.44 | ED6: 3.35 | EE6: 0.71171 | EF6: 0.97 | EG6: 1.08 | EH6: 2.4 | EI6: 965 | EJ6: 3546 | EK6: 7.8 | EL6: 64.8954 | EM6: 2 | EN6: 11.113 | EO6: 10 | EP6: 9 | EQ6: 28.07 | ER6: 0.931 | ES6: 2 | ET6: 198 | EU6: 2.243 | EV6: 223 | EW6: 1.5 | EX6: 1.3 | EY6: 6.299 | EZ6: 1.0694747 | FA6: 0.022280723 | FC6: =EZ10 -> 1.9398047 | FD6: -1833.7609 | FE6: =FD6/M6 -> -7.6726396 | FF6: =FE6*1000 -> -7672.6396 | FG6: 4.0075325 | FH6: 4.00783 | FI6: 4.123 | FJ6: 66.221554 | FK6: =FJ6/M6 -> 0.27707763 | FM6: =FJ10 -> 66.87086 | FN6: -0.88 | FO6: 1.92 | FP6: 2.8 | FQ6: =FP6+0.01 -> 2.81 | FR6: =FQ6-2.86 -> -0.05 | FS6: =IF(FR6<0,0,1) -> 0
A7: K23 Ba1 Na23 Nb48 O144 | B7: Nb | C7: 48 | D7: O | E7: 144 | F7: K | G7: 23 | H7: Na | I7: 23 | J7: Ba | K7: 1 | M7: =C7+E7+G7+I7+K7 -> 239 | P7: 1.92 | Q7: 14 | R7: 3573 | S7: 1.702 | T7: 8570 | U7: 0.95 | V7: 1.75 | W7: 0.19256 | X7: 1.23 | Y7: 2.03 | Z7: 4 | AA7: 1382 | AB7: 2416 | AC7: 26.8 | AD7: 36.28 | AE7: 5 | AF7: 24.442 | AG7: 58 | AH7: 50 | AI7: 24.48 | AJ7: 6.144 | AK7: 3 | AL7: 134 | AM7: 1.468 | AN7: 450 | AO7: 4.5 | AP7: 1.15 | AQ7: 1.807 | AR7: 0.232 | AS7: 1 | AT7: 90.19 | AU7: 0.011 | AV7: 2000 | AW7: 0.85 | AX7: 1.2 | AY7: 0.82902 | AZ7: 3.5 | BA7: 3.32 | BB7: 7.54 | BC7: 3388 | BD7: 5300 | BE7: 0.444 | BF7: 205.19507 | BG7: 6 | BH7: 13.557 | BI7: 103 | BJ7: 92 | BK7: 29.355 | BL7: -1.893 | BM7: -2 | BN7: 66 | BO7: 0.89 | BP7: 192 | BQ7: 2.5 | BR7: 0.0028 | BS7: 1.736 | BT7: 0.43 | BU7: 14 | BV7: 1032 | BW7: 0.032 | BX7: 862 | BY7: 1.32 | BZ7: 4.6 | CA7: 0.40514 | CB7: 0.91 | CC7: 0.8 | CD7: 2.42 | CE7: 3051 | CF7: 4411 | CG7: 2.39 | CH7: 64.43485 | CI7: 1 | CJ7: 4.667 | CK7: 6 | CL7: 4 | CM7: 29.58 | CN7: 0.391 | CO7: 1 | CP7: 203 | CQ7: 2.376 | CR7: 87 | CS7: 1.5 | CT7: 2.1 | CU7: 7.572 | CV7: 0.278 | CW7: 14 | CX7: 1153 | CY7: 0.068 | CZ7: 971 | DA7: 1.07 | DB7: 3.73 | DC7: 0.23831 | DD7: 1.01 | DE7: 0.89 | DF7: 2.85 | DG7: 4562 | DH7: 6912 | DI7: 2.64 | DJ7: 51.12083 | DK7: 1 | DL7: 26.451 | DM7: 7 | DN7: 5 | DO7: 28.24 | DP7: 2.216 | DQ7: 1 | DR7: 154 | DS7: 1.911 | DT7: 83 | DU7: 1.5 | DV7: 0.53 | DW7: 3.926 | DX7: 2.45 | DY7: 14 | DZ7: 1910 | EA7: 0.103 | EB7: 3594 | EC7: 1.44 | ED7: 3.35 | EE7: 0.71171 | EF7: 0.97 | EG7: 1.08 | EH7: 2.4 | EI7: 965 | EJ7: 3546 | EK7: 7.8 | EL7: 64.8954 | EM7: 2 | EN7: 11.113 | EO7: 10 | EP7: 9 | EQ7: 28.07 | ER7: 0.931 | ES7: 2 | ET7: 198 | EU7: 2.243 | EV7: 223 | EW7: 1.5 | EX7: 1.3 | EY7: 6.299 | EZ7: 1.1549066 | FA7: 0.024060553 | FC7: =EZ11 -> 1.7649796 | FD7: -1833.3912 | FE7: =FD7/M7 -> -7.6710929 | FF7: =FE7*1000 -> -7671.0929 | FG7: 4.007405 | FH7: 4.0094125 | FI7: 4.1269567 | FJ7: 66.309207 | FK7: =FJ7/M7 -> 0.27744438 | FM7: =FJ11 -> 66.435855 | FN7: -0.85 | FO7: 1.82 | FP7: 2.67 | FQ7: =FP7+0.01 -> 2.68 | FR7: =FQ7-2.86 -> -0.18 | FS7: =IF(FR7<0,0,1) -> 0
A8: K23 Ba1 Na24 Nb47 O144 | B8: Nb | C8: 47 | D8: O | E8: 144 | F8: K | G8: 23 | H8: Na | I8: 24 | J8: Ba | K8: 1 | M8: =C8+E8+G8+I8+K8 -> 239 | P8: 1.92 | Q8: 14 | R8: 3573 | S8: 1.702 | T8: 8570 | U8: 0.95 | V8: 1.75 | W8: 0.19256 | X8: 1.23 | Y8: 2.03 | Z8: 4 | AA8: 1382 | AB8: 2416 | AC8: 26.8 | AD8: 36.28 | AE8: 5 | AF8: 24.442 | AG8: 58 | AH8: 50 | AI8: 24.48 | AJ8: 6.144 | AK8: 3 | AL8: 134 | AM8: 1.468 | AN8: 450 | AO8: 4.5 | AP8: 1.15 | AQ8: 1.807 | AR8: 0.232 | AS8: 1 | AT8: 90.19 | AU8: 0.011 | AV8: 2000 | AW8: 0.85 | AX8: 1.2 | AY8: 0.82902 | AZ8: 3.5 | BA8: 3.32 | BB8: 7.54 | BC8: 3388 | BD8: 5300 | BE8: 0.444 | BF8: 205.19507 | BG8: 6 | BH8: 13.557 | BI8: 103 | BJ8: 92 | BK8: 29.355 | BL8: -1.893 | BM8: -2 | BN8: 66 | BO8: 0.89 | BP8: 192 | BQ8: 2.5 | BR8: 0.0028 | BS8: 1.736 | BT8: 0.43 | BU8: 14 | BV8: 1032 | BW8: 0.032 | BX8: 862 | BY8: 1.32 | BZ8: 4.6 | CA8: 0.40514 | CB8: 0.91 | CC8: 0.8 | CD8: 2.42 | CE8: 3051 | CF8: 4411 | CG8: 2.39 | CH8: 64.43485 | CI8: 1 | CJ8: 4.667 | CK8: 6 | CL8: 4 | CM8: 29.58 | CN8: 0.391 | CO8: 1 | CP8: 203 | CQ8: 2.376 | CR8: 87 | CS8: 1.5 | CT8: 2.1 | CU8: 7.572 | CV8: 0.278 | CW8: 14 | CX8: 1153 | CY8: 0.068 | CZ8: 971 | DA8: 1.07 | DB8: 3.73 | DC8: 0.23831 | DD8: 1.01 | DE8: 0.89 | DF8: 2.85 | DG8: 4562 | DH8: 6912 | DI8: 2.64 | DJ8: 51.12083 | DK8: 1 | DL8: 26.451 | DM8: 7 | DN8: 5 | DO8: 28.24 | DP8: 2.216 | DQ8: 1 | DR8: 154 | DS8: 1.911 | DT8: 83 | DU8: 1.5 | DV8: 0.53 | DW8: 3.926 | DX8: 2.45 | DY8: 14 | DZ8: 1910 | EA8: 0.103 | EB8: 3594 | EC8: 1.44 | ED8: 3.35 | EE8: 0.71171 | EF8: 0.97 | EG8: 1.08 | EH8: 2.4 | EI8: 965 | EJ8: 3546 | EK8: 7.8 | EL8: 64.8954 | EM8: 2 | EN8: 11.113 | EO8: 10 | EP8: 9 | EQ8: 28.07 | ER8: 0.931 | ES8: 2 | ET8: 198 | EU8: 2.243 | EV8: 223 | EW8: 1.5 | EX8: 1.3 | EY8: 6.299 | EZ8: 13.970723 | FA8: 0.29105672 | FC8: =EZ12 -> 13.333055 | FD8: -1811.7938 | FE8: =FD8/M8 -> -7.5807272 | FF8: =FE8*1000 -> -7580.7272 | FG8: 4.01056 | FH8: 4.0104625 | FI8: 4.1307933 | FJ8: 66.440508 | FK8: =FJ8/M8 -> 0.27799376 | FM8: =FJ12 -> 66.400494 | FN8: -1.13 | FO8: 2.21 | FP8: 3.34 | FQ8: =FP8+0.01 -> 3.35 | FR8: =FQ8-2.86 -> 0.49 | FS8: =IF(FR8<0,0,1) -> 1
A9: K23 Ba1 Na24 Nb48 O143 | B9: Nb | C9: 48 | D9: O | E9: 143 | F9: K | G9: 23 | H9: Na | I9: 24 | J9: Ba | K9: 1 | M9: =C9+E9+G9+I9+K9 -> 239 | P9: 1.92 | Q9: 14 | R9: 3573 | S9: 1.702 | T9: 8570 | U9: 0.95 | V9: 1.75 | W9: 0.19256 | X9: 1.23 | Y9: 2.03 | Z9: 4 | AA9: 1382 | AB9: 2416 | AC9: 26.8 | AD9: 36.28 | AE9: 5 | AF9: 24.442 | AG9: 58 | AH9: 50 | AI9: 24.48 | AJ9: 6.144 | AK9: 3 | AL9: 134 | AM9: 1.468 | AN9: 450 | AO9: 4.5 | AP9: 1.15 | AQ9: 1.807 | AR9: 0.232 | AS9: 1 | AT9: 90.19 | AU9: 0.011 | AV9: 2000 | AW9: 0.85 | AX9: 1.2 | AY9: 0.82902 | AZ9: 3.5 | BA9: 3.32 | BB9: 7.54 | BC9: 3388 | BD9: 5300 | BE9: 0.444 | BF9: 205.19507 | BG9: 6 | BH9: 13.557 | BI9: 103 | BJ9: 92 | BK9: 29.355 | BL9: -1.893 | BM9: -2 | BN9: 66 | BO9: 0.89 | BP9: 192 | BQ9: 2.5 | BR9: 0.0028 | BS9: 1.736 | BT9: 0.43 | BU9: 14 | BV9: 1032 | BW9: 0.032 | BX9: 862 | BY9: 1.32 | BZ9: 4.6 | CA9: 0.40514 | CB9: 0.91 | CC9: 0.8 | CD9: 2.42 | CE9: 3051 | CF9: 4411 | CG9: 2.39 | CH9: 64.43485 | CI9: 1 | CJ9: 4.667 | CK9: 6 | CL9: 4 | CM9: 29.58 | CN9: 0.391 | CO9: 1 | CP9: 203 | CQ9: 2.376 | CR9: 87 | CS9: 1.5 | CT9: 2.1 | CU9: 7.572 | CV9: 0.278 | CW9: 14 | CX9: 1153 | CY9: 0.068 | CZ9: 971 | DA9: 1.07 | DB9: 3.73 | DC9: 0.23831 | DD9: 1.01 | DE9: 0.89 | DF9: 2.85 | DG9: 4562 | DH9: 6912 | DI9: 2.64 | DJ9: 51.12083 | DK9: 1 | DL9: 26.451 | DM9: 7 | DN9: 5 | DO9: 28.24 | DP9: 2.216 | DQ9: 1 | DR9: 154 | DS9: 1.911 | DT9: 83 | DU9: 1.5 | DV9: 0.53 | DW9: 3.926 | DX9: 2.45 | DY9: 14 | DZ9: 1910 | EA9: 0.103 | EB9: 3594 | EC9: 1.44 | ED9: 3.35 | EE9: 0.71171 | EF9: 0.97 | EG9: 1.08 | EH9: 2.4 | EI9: 965 | EJ9: 3546 | EK9: 7.8 | EL9: 64.8954 | EM9: 2 | EN9: 11.113 | EO9: 10 | EP9: 9 | EQ9: 28.07 | ER9: 0.931 | ES9: 2 | ET9: 198 | EU9: 2.243 | EV9: 223 | EW9: 1.5 | EX9: 1.3 | EY9: 6.299 | EZ9: 5.6869536 | FA9: 0.1184782 | FC9: =EZ13 -> 4.8267596 | FD9: -1825.222 | FE9: =FD9/M9 -> -7.636912 | FF9: =FE9*1000 -> -7636.912 | FG9: 4.009135 | FH9: 4.0114075 | FI9: 4.1255367 | FJ9: 66.347985 | FK9: =FJ9/M9 -> 0.27760663 | FM9: =FJ13 -> 66.322786 | FN9: -0.87 | FO9: 2.11 | FP9: 2.98 | FQ9: =FP9+0.01 -> 2.99 | FR9: =FQ9-2.86 -> 0.13 | FS9: =IF(FR9<0,0,1) -> 1
A10: K23 Ba1 Na23 Nb48 O144 | B10: Nb | C10: 48 | D10: O | E10: 144 | F10: K | G10: 23 | H10: Na | I10: 23 | J10: Ba | K10: 1 | M10: =C10+E10+G10+I10+K10 -> 239 | P10: 1.92 | Q10: 14 | R10: 3573 | S10: 1.702 | T10: 8570 | U10: 0.95 | V10: 1.75 | W10: 0.19256 | X10: 1.23 | Y10: 2.03 | Z10: 4 | AA10: 1382 | AB10: 2416 | AC10: 26.8 | AD10: 36.28 | AE10: 5 | AF10: 24.442 | AG10: 58 | AH10: 50 | AI10: 24.48 | AJ10: 6.144 | AK10: 3 | AL10: 134 | AM10: 1.468 | AN10: 450 | AO10: 4.5 | AP10: 1.15 | AQ10: 1.807 | AR10: 0.232 | AS10: 1 | AT10: 90.19 | AU10: 0.011 | AV10: 2000 | AW10: 0.85 | AX10: 1.2 | AY10: 0.82902 | AZ10: 3.5 | BA10: 3.32 | BB10: 7.54 | BC10: 3388 | BD10: 5300 | BE10: 0.444 | BF10: 205.19507 | BG10: 6 | BH10: 13.557 | BI10: 103 | BJ10: 92 | BK10: 29.355 | BL10: -1.893 | BM10: -2 | BN10: 66 | BO10: 0.89 | BP10: 192 | BQ10: 2.5 | BR10: 0.0028 | BS10: 1.736 | BT10: 0.43 | BU10: 14 | BV10: 1032 | BW10: 0.032 | BX10: 862 | BY10: 1.32 | BZ10: 4.6 | CA10: 0.40514 | CB10: 0.91 | CC10: 0.8 | CD10: 2.42 | CE10: 3051 | CF10: 4411 | CG10: 2.39 | CH10: 64.43485 | CI10: 1 | CJ10: 4.667 | CK10: 6 | CL10: 4 | CM10: 29.58 | CN10: 0.391 | CO10: 1 | CP10: 203 | CQ10: 2.376 | CR10: 87 | CS10: 1.5 | CT10: 2.1 | CU10: 7.572 | CV10: 0.278 | CW10: 14 | CX10: 1153 | CY10: 0.068 | CZ10: 971 | DA10: 1.07 | DB10: 3.73 | DC10: 0.23831 | DD10: 1.01 | DE10: 0.89 | DF10: 2.85 | DG10: 4562 | DH10: 6912 | DI10: 2.64 | DJ10: 51.12083 | DK10: 1 | DL10: 26.451 | DM10: 7 | DN10: 5 | DO10: 28.24 | DP10: 2.216 | DQ10: 1 | DR10: 154 | DS10: 1.911 | DT10: 83 | DU10: 1.5 | DV10: 0.53 | DW10: 3.926 | DX10: 2.45 | DY10: 14 | DZ10: 1910 | EA10: 0.103 | EB10: 3594 | EC10: 1.44 | ED10: 3.35 | EE10: 0.71171 | EF10: 0.97 | EG10: 1.08 | EH10: 2.4 | EI10: 965 | EJ10: 3546 | EK10: 7.8 | EL10: 64.8954 | EM10: 2 | EN10: 11.113 | EO10: 10 | EP10: 9 | EQ10: 28.07 | ER10: 0.931 | ES10: 2 | ET10: 198 | EU10: 2.243 | EV10: 223 | EW10: 1.5 | EX10: 1.3 | EY10: 6.299 | EZ10: 1.9398047 | FA10: 0.040412598 | FD10: -1832.9291 | FE10: =FD10/M10 -> -7.6691594 | FF10: =FE10*1000 -> -7669.1594 | FG10: 4.0085975 | FH10: 4.0083225 | FI10: 4.16181 | FJ10: 66.87086 | FK10: =FJ10/M10 -> 0.2797944 | FN10: -1.01 | FO10: 2.07 | FP10: 3.08 | FQ10: =FP10+0.01 -> 3.09 | FR10: =FQ10-2.86 -> 0.23 | FS10: =IF(FR10<0,0,1) -> 1
A11: K24 Ba1 Na22 Nb48 O144 | B11: Nb | C11: 48 | D11: O | E11: 144 | F11: K | G11: 24 | H11: Na | I11: 22 | J11: Ba | K11: 1 | M11: =C11+E11+G11+I11+K11 -> 239 | P11: 1.92 | Q11: 14 | R11: 3573 | S11: 1.702 | T11: 8570 | U11: 0.95 | V11: 1.75 | W11: 0.19256 | X11: 1.23 | Y11: 2.03 | Z11: 4 | AA11: 1382 | AB11: 2416 | AC11: 26.8 | AD11: 36.28 | AE11: 5 | AF11: 24.442 | AG11: 58 | AH11: 50 | AI11: 24.48 | AJ11: 6.144 | AK11: 3 | AL11: 134 | AM11: 1.468 | AN11: 450 | AO11: 4.5 | AP11: 1.15 | AQ11: 1.807 | AR11: 0.232 | AS11: 1 | AT11: 90.19 | AU11: 0.011 | AV11: 2000 | AW11: 0.85 | AX11: 1.2 | AY11: 0.82902 | AZ11: 3.5 | BA11: 3.32 | BB11: 7.54 | BC11: 3388 | BD11: 5300 | BE11: 0.444 | BF11: 205.19507 | BG11: 6 | BH11: 13.557 | BI11: 103 | BJ11: 92 | BK11: 29.355 | BL11: -1.893 | BM11: -2 | BN11: 66 | BO11: 0.89 | BP11: 192 | BQ11: 2.5 | BR11: 0.0028 | BS11: 1.736 | BT11: 0.43 | BU11: 14 | BV11: 1032 | BW11: 0.032 | BX11: 862 | BY11: 1.32 | BZ11: 4.6 | CA11: 0.40514 | CB11: 0.91 | CC11: 0.8 | CD11: 2.42 | CE11: 3051 | CF11: 4411 | CG11: 2.39 | CH11: 64.43485 | CI11: 1 | CJ11: 4.667 | CK11: 6 | CL11: 4 | CM11: 29.58 | CN11: 0.391 | CO11: 1 | CP11: 203 | CQ11: 2.376 | CR11: 87 | CS11: 1.5 | CT11: 2.1 | CU11: 7.572 | CV11: 0.278 | CW11: 14 | CX11: 1153 | CY11: 0.068 | CZ11: 971 | DA11: 1.07 | DB11: 3.73 | DC11: 0.23831 | DD11: 1.01 | DE11: 0.89 | DF11: 2.85 | DG11: 4562 | DH11: 6912 | DI11: 2.64 | DJ11: 51.12083 | DK11: 1 | DL11: 26.451 | DM11: 7 | DN11: 5 | DO11: 28.24 | DP11: 2.216 | DQ11: 1 | DR11: 154 | DS11: 1.911 | DT11: 83 | DU11: 1.5 | DV11: 0.53 | DW11: 3.926 | DX11: 2.45 | DY11: 14 | DZ11: 1910 | EA11: 0.103 | EB11: 3594 | EC11: 1.44 | ED11: 3.35 | EE11: 0.71171 | EF11: 0.97 | EG11: 1.08 | EH11: 2.4 | EI11: 965 | EJ11: 3546 | EK11: 7.8 | EL11: 64.8954 | EM11: 2 | EN11: 11.113 | EO11: 10 | EP11: 9 | EQ11: 28.07 | ER11: 0.931 | ES11: 2 | ET11: 198 | EU11: 2.243 | EV11: 223 | EW11: 1.5 | EX11: 1.3 | EY11: 6.299 | EZ11: 1.7649796 | FA11: 0.036770407 | FC11: =MAX(FE2:FE301)-MIN(FE2:FE301) -> 0.14030038 | FD11: -1832.8197 | FE11: =FD11/M11 -> -7.6687017 | FF11: =FE11*1000 -> -7668.7017 | FG11: 4.006855 | FH11: 4.00687 | FI11: 4.13803 | FJ11: 66.435855 | FK11: =FJ11/M11 -> 0.27797429 | FN11: -0.95 | FO11: 2.06 | FP11: 3.01 | FQ11: =FP11+0.01 -> 3.02 | FR11: =FQ11-2.86 -> 0.16 | FS11: =IF(FR11<0,0,1) -> 1
A12: K24 Ba1 Na23 Nb47 O144 | B12: Nb | C12: 47 | D12: O | E12: 144 | F12: K | G12: 24 | H12: Na | I12: 23 | J12: Ba | K12: 1 | M12: =C12+E12+G12+I12+K12 -> 239 | P12: 1.92 | Q12: 14 | R12: 3573 | S12: 1.702 | T12: 8570 | U12: 0.95 | V12: 1.75 | W12: 0.19256 | X12: 1.23 | Y12: 2.03 | Z12: 4 | AA12: 1382 | AB12: 2416 | AC12: 26.8 | AD12: 36.28 | AE12: 5 | AF12: 24.442 | AG12: 58 | AH12: 50 | AI12: 24.48 | AJ12: 6.144 | AK12: 3 | AL12: 134 | AM12: 1.468 | AN12: 450 | AO12: 4.5 | AP12: 1.15 | AQ12: 1.807 | AR12: 0.232 | AS12: 1 | AT12: 90.19 | AU12: 0.011 | AV12: 2000 | AW12: 0.85 | AX12: 1.2 | AY12: 0.82902 | AZ12: 3.5 | BA12: 3.32 | BB12: 7.54 | BC12: 3388 | BD12: 5300 | BE12: 0.444 | BF12: 205.19507 | BG12: 6 | BH12: 13.557 | BI12: 103 | BJ12: 92 | BK12: 29.355 | BL12: -1.893 | BM12: -2 | BN12: 66 | BO12: 0.89 | BP12: 192 | BQ12: 2.5 | BR12: 0.0028 | BS12: 1.736 | BT12: 0.43 | BU12: 14 | BV12: 1032 | BW12: 0.032 | BX12: 862 | BY12: 1.32 | BZ12: 4.6 | CA12: 0.40514 | CB12: 0.91 | CC12: 0.8 | CD12: 2.42 | CE12: 3051 | CF12: 4411 | CG12: 2.39 | CH12: 64.43485 | CI12: 1 | CJ12: 4.667 | CK12: 6 | CL12: 4 | CM12: 29.58 | CN12: 0.391 | CO12: 1 | CP12: 203 | CQ12: 2.376 | CR12: 87 | CS12: 1.5 | CT12: 2.1 | CU12: 7.572 | CV12: 0.278 | CW12: 14 | CX12: 1153 | CY12: 0.068 | CZ12: 971 | DA12: 1.07 | DB12: 3.73 | DC12: 0.23831 | DD12: 1.01 | DE12: 0.89 | DF12: 2.85 | DG12: 4562 | DH12: 6912 | DI12: 2.64 | DJ12: 51.12083 | DK12: 1 | DL12: 26.451 | DM12: 7 | DN12: 5 | DO12: 28.24 | DP12: 2.216 | DQ12: 1 | DR12: 154 | DS12: 1.911 | DT12: 83 | DU12: 1.5 | DV12: 0.53 | DW12: 3.926 | DX12: 2.45 | DY12: 14 | DZ12: 1910 | EA12: 0.103 | EB12: 3594 | EC12: 1.44 | ED12: 3.35 | EE12: 0.71171 | EF12: 0.97 | EG12: 1.08 | EH12: 2.4 | EI12: 965 | EJ12: 3546 | EK12: 7.8 | EL12: 64.8954 | EM12: 2 | EN12: 11.113 | EO12: 10 | EP12: 9 | EQ12: 28.07 | ER12: 0.931 | ES12: 2 | ET12: 198 | EU12: 2.243 | EV12: 223 | EW12: 1.5 | EX12: 1.3 | EY12: 6.299 | EZ12: 13.333055 | FA12: 0.27777197 | FD12: -1812.47 | FE12: =FD12/M12 -> -7.5835566 | FF12: =FE12*1000 -> -7583.5566 | FG12: 4.0099475 | FH12: 4.0092625 | FI12: 4.1301733 | FJ12: 66.400494 | FK12: =FJ12/M12 -> 0.27782634 | FN12: -1.08 | FO12: 1.9 | FP12: 2.98 | FQ12: =FP12+0.01 -> 2.99 | FR12: =FQ12-2.86 -> 0.13 | FS12: =IF(FR12<0,0,1) -> 1
A13: K24 Ba1 Na23 Nb48 O143 | B13: Nb | C13: 48 | D13: O | E13: 143 | F13: K | G13: 24 | H13: Na | I13: 23 | J13: Ba | K13: 1 | M13: =C13+E13+G13+I13+K13 -> 239 | P13: 1.92 | Q13: 14 | R13: 3573 | S13: 1.702 | T13: 8570 | U13: 0.95 | V13: 1.75 | W13: 0.19256 | X13: 1.23 | Y13: 2.03 | Z13: 4 | AA13: 1382 | AB13: 2416 | AC13: 26.8 | AD13: 36.28 | AE13: 5 | AF13: 24.442 | AG13: 58 | AH13: 50 | AI13: 24.48 | AJ13: 6.144 | AK13: 3 | AL13: 134 | AM13: 1.468 | AN13: 450 | AO13: 4.5 | AP13: 1.15 | AQ13: 1.807 | AR13: 0.232 | AS13: 1 | AT13: 90.19 | AU13: 0.011 | AV13: 2000 | AW13: 0.85 | AX13: 1.2 | AY13: 0.82902 | AZ13: 3.5 | BA13: 3.32 | BB13: 7.54 | BC13: 3388 | BD13: 5300 | BE13: 0.444 | BF13: 205.19507 | BG13: 6 | BH13: 13.557 | BI13: 103 | BJ13: 92 | BK13: 29.355 | BL13: -1.893 | BM13: -2 | BN13: 66 | BO13: 0.89 | BP13: 192 | BQ13: 2.5 | BR13: 0.0028 | BS13: 1.736 | BT13: 0.43 | BU13: 14 | BV13: 1032 | BW13: 0.032 | BX13: 862 | BY13: 1.32 | BZ13: 4.6 | CA13: 0.40514 | CB13: 0.91 | CC13: 0.8 | CD13: 2.42 | CE13: 3051 | CF13: 4411 | CG13: 2.39 | CH13: 64.43485 | CI13: 1 | CJ13: 4.667 | CK13: 6 | CL13: 4 | CM13: 29.58 | CN13: 0.391 | CO13: 1 | CP13: 203 | CQ13: 2.376 | CR13: 87 | CS13: 1.5 | CT13: 2.1 | CU13: 7.572 | CV13: 0.278 | CW13: 14 | CX13: 1153 | CY13: 0.068 | CZ13: 971 | DA13: 1.07 | DB13: 3.73 | DC13: 0.23831 | DD13: 1.01 | DE13: 0.89 | DF13: 2.85 | DG13: 4562 | DH13: 6912 | DI13: 2.64 | DJ13: 51.12083 | DK13: 1 | DL13: 26.451 | DM13: 7 | DN13: 5 | DO13: 28.24 | DP13: 2.216 | DQ13: 1 | DR13: 154 | DS13: 1.911 | DT13: 83 | DU13: 1.5 | DV13: 0.53 | DW13: 3.926 | DX13: 2.45 | DY13: 14 | DZ13: 1910 | EA13: 0.103 | EB13: 3594 | EC13: 1.44 | ED13: 3.35 | EE13: 0.71171 | EF13: 0.97 | EG13: 1.08 | EH13: 2.4 | EI13: 965 | EJ13: 3546 | EK13: 7.8 | EL13: 64.8954 | EM13: 2 | EN13: 11.113 | EO13: 10 | EP13: 9 | EQ13: 28.07 | ER13: 0.931 | ES13: 2 | ET13: 198 | EU13: 2.243 | EV13: 223 | EW13: 1.5 | EX13: 1.3 | EY13: 6.299 | EZ13: 4.8267596 | FA13: 0.10055749 | FD13: -1826.1207 | FE13: =FD13/M13 -> -7.6406725 | FF13: =FE13*1000 -> -7640.6725 | FG13: 4.0066425 | FH13: 4.0080025 | FI13: 4.13004 | FJ13: 66.322786 | FK13: =FJ13/M13 -> 0.2775012 | FN13: -0.9 | FO13: 2.16 | FP13: 3.06 | FQ13: =FP13+0.01 -> 3.07 | FR13: =FQ13-2.86 -> 0.21 | FS13: =IF(FR13<0,0,1) -> 1
A14: K23 Na24 Sr1 Nb48 O144 | B14: Nb | C14: 48 | D14: O | E14: 144 | F14: K | G14: 23 | H14: Na | I14: 24 | J14: Sr | K14: 1 | M14: =C14+E14+G14+I14+K14 -> 240 | P14: 1.92 | Q14: 14 | R14: 3573 | S14: 1.702 | T14: 8570 | U14: 0.95 | V14: 1.75 | W14: 0.19256 | X14: 1.23 | Y14: 2.03 | Z14: 4 | AA14: 1382 | AB14: 2416 | AC14: 26.8 | AD14: 36.28 | AE14: 5 | AF14: 24.442 | AG14: 58 | AH14: 50 | AI14: 24.48 | AJ14: 6.144 | AK14: 3 | AL14: 134 | AM14: 1.468 | AN14: 450 | AO14: 4.5 | AP14: 1.15 | AQ14: 1.807 | AR14: 0.232 | AS14: 1 | AT14: 90.19 | AU14: 0.011 | AV14: 2000 | AW14: 0.85 | AX14: 1.2 | AY14: 0.82902 | AZ14: 3.5 | BA14: 3.32 | BB14: 7.54 | BC14: 3388 | BD14: 5300 | BE14: 0.444 | BF14: 205.19507 | BG14: 6 | BH14: 13.557 | BI14: 103 | BJ14: 92 | BK14: 29.355 | BL14: -1.893 | BM14: -2 | BN14: 66 | BO14: 0.89 | BP14: 192 | BQ14: 2.5 | BR14: 0.0028 | BS14: 1.736 | BT14: 0.43 | BU14: 14 | BV14: 1032 | BW14: 0.032 | BX14: 862 | BY14: 1.32 | BZ14: 4.6 | CA14: 0.40514 | CB14: 0.91 | CC14: 0.8 | CD14: 2.42 | CE14: 3051 | CF14: 4411 | CG14: 2.39 | CH14: 64.43485 | CI14: 1 | CJ14: 4.667 | CK14: 6 | CL14: 4 | CM14: 29.58 | CN14: 0.391 | CO14: 1 | CP14: 203 | CQ14: 2.376 | CR14: 87 | CS14: 1.5 | CT14: 2.1 | CU14: 7.572 | CV14: 0.278 | CW14: 14 | CX14: 1153 | CY14: 0.068 | CZ14: 971 | DA14: 1.07 | DB14: 3.73 | DC14: 0.23831 | DD14: 1.01 | DE14: 0.89 | DF14: 2.85 | DG14: 4562 | DH14: 6912 | DI14: 2.64 | DJ14: 51.12083 | DK14: 1 | DL14: 26.451 | DM14: 7 | DN14: 5 | DO14: 28.24 | DP14: 2.216 | DQ14: 1 | DR14: 154 | DS14: 1.911 | DT14: 83 | DU14: 1.5 | DV14: 0.53 | DW14: 3.926 | DX14: 1.8 | DY14: 12 | DZ14: 1653 | EA14: 0.116 | EB14: 2540 | EC14: 1.39 | ED14: 2.92 | EE14: 0.45404 | EF14: 0.99 | EG14: 1.13 | EH14: 2 | EI14: 1064 | EJ14: 4207 | EK14: 8.2 | EL14: 52.335 | EM14: 2 | EN14: 4.333 | EO14: 11 | EP14: 10 | EQ14: 26.4 | ER14: 1.089 | ES14: 2 | ET14: 192 | EU14: 2.151 | EV14: 92 | EW14: 4.5 | EX14: 1.2 | EY14: 5.632 | EZ14: -1.3512023 | FB14: =EZ14 -> -1.3512023 | FD14: -1835.8667 | FE14: =FD14/M14 -> -7.6494445 | FF14: =FE14*1000 -> -7649.4445 | FG14: 4.030485 | FH14: 4.0302075 | FI14: 4.1209 | FJ14: 66.93866 | FK14: =FJ14/M14 -> 0.27891109 | FL14: =FJ14 -> 66.93866 | FN14: -0.86 | FO14: 1.93 | FP14: 2.79 | FQ14: =FP14+0.01 -> 2.8 | FR14: =FQ14-2.86 -> -0.06 | FS14: =IF(FR14<0,0,1) -> 0
A15: K24 Na23 Sr1 Nb48 O144 | B15: Nb | C15: 48 | D15: O | E15: 144 | F15: K | G15: 24 | H15: Na | I15: 23 | J15: Sr | K15: 1 | M15: =C15+E15+G15+I15+K15 -> 240 | P15: 1.92 | Q15: 14 | R15: 3573 | S15: 1.702 | T15: 8570 | U15: 0.95 | V15: 1.75 | W15: 0.19256 | X15: 1.23 | Y15: 2.03 | Z15: 4 | AA15: 1382 | AB15: 2416 | AC15: 26.8 | AD15: 36.28 | AE15: 5 | AF15: 24.442 | AG15: 58 | AH15: 50 | AI15: 24.48 | AJ15: 6.144 | AK15: 3 | AL15: 134 | AM15: 1.468 | AN15: 450 | AO15: 4.5 | AP15: 1.15 | AQ15: 1.807 | AR15: 0.232 | AS15: 1 | AT15: 90.19 | AU15: 0.011 | AV15: 2000 | AW15: 0.85 | AX15: 1.2 | AY15: 0.82902 | AZ15: 3.5 | BA15: 3.32 | BB15: 7.54 | BC15: 3388 | BD15: 5300 | BE15: 0.444 | BF15: 205.19507 | BG15: 6 | BH15: 13.557 | BI15: 103 | BJ15: 92 | BK15: 29.355 | BL15: -1.893 | BM15: -2 | BN15: 66 | BO15: 0.89 | BP15: 192 | BQ15: 2.5 | BR15: 0.0028 | BS15: 1.736 | BT15: 0.43 | BU15: 14 | BV15: 1032 | BW15: 0.032 | BX15: 862 | BY15: 1.32 | BZ15: 4.6 | CA15: 0.40514 | CB15: 0.91 | CC15: 0.8 | CD15: 2.42 | CE15: 3051 | CF15: 4411 | CG15: 2.39 | CH15: 64.43485 | CI15: 1 | CJ15: 4.667 | CK15: 6 | CL15: 4 | CM15: 29.58 | CN15: 0.391 | CO15: 1 | CP15: 203 | CQ15: 2.376 | CR15: 87 | CS15: 1.5 | CT15: 2.1 | CU15: 7.572 | CV15: 0.278 | CW15: 14 | CX15: 1153 | CY15: 0.068 | CZ15: 971 | DA15: 1.07 | DB15: 3.73 | DC15: 0.23831 | DD15: 1.01 | DE15: 0.89 | DF15: 2.85 | DG15: 4562 | DH15: 6912 | DI15: 2.64 | DJ15: 51.12083 | DK15: 1 | DL15: 26.451 | DM15: 7 | DN15: 5 | DO15: 28.24 | DP15: 2.216 | DQ15: 1 | DR15: 154 | DS15: 1.911 | DT15: 83 | DU15: 1.5 | DV15: 0.53 | DW15: 3.926 | DX15: 1.8 | DY15: 12 | DZ15: 1653 | EA15: 0.116 | EB15: 2540 | EC15: 1.39 | ED15: 2.92 | EE15: 0.45404 | EF15: 0.99 | EG15: 1.13 | EH15: 2 | EI15: 1064 | EJ15: 4207 | EK15: 8.2 | EL15: 52.335 | EM15: 2 | EN15: 4.333 | EO15: 11 | EP15: 10 | EQ15: 26.4 | ER15: 1.089 | ES15: 2 | ET15: 192 | EU15: 2.151 | EV15: 92 | EW15: 4.5 | EX15: 1.2 | EY15: 5.632 | EZ15: -1.5985565 | FB15: =EZ15 -> -1.5985565 | FD15: -1835.8298 | FE15: =FD15/M15 -> -7.6492909 | FF15: =FE15*1000 -> -7649.2909 | FG15: 4.0307175 | FH15: 4.0303975 | FI15: 4.1208667 | FJ15: 66.945137 | FK15: =FJ15/M15 -> 0.27893807 | FL15: =FJ15 -> 66.945137 | FN15: -0.96 | FO15: 1.96 | FP15: 2.92 | FQ15: =FP15+0.01 -> 2.93 | FR15: =FQ15-2.86 -> 0.07 | FS15: =IF(FR15<0,0,1) -> 1
A16: K24 Na24 Sr1 Nb47 O144 | B16: Nb | C16: 47 | D16: O | E16: 144 | F16: K | G16: 24 | H16: Na | I16: 24 | J16: Sr | K16: 1 | M16: =C16+E16+G16+I16+K16 -> 240 | P16: 1.92 | Q16: 14 | R16: 3573 | S16: 1.702 | T16: 8570 | U16: 0.95 | V16: 1.75 | W16: 0.19256 | X16: 1.23 | Y16: 2.03 | Z16: 4 | AA16: 1382 | AB16: 2416 | AC16: 26.8 | AD16: 36.28 | AE16: 5 | AF16: 24.442 | AG16: 58 | AH16: 50 | AI16: 24.48 | AJ16: 6.144 | AK16: 3 | AL16: 134 | AM16: 1.468 | AN16: 450 | AO16: 4.5 | AP16: 1.15 | AQ16: 1.807 | AR16: 0.232 | AS16: 1 | AT16: 90.19 | AU16: 0.011 | AV16: 2000 | AW16: 0.85 | AX16: 1.2 | AY16: 0.82902 | AZ16: 3.5 | BA16: 3.32 | BB16: 7.54 | BC16: 3388 | BD16: 5300 | BE16: 0.444 | BF16: 205.19507 | BG16: 6 | BH16: 13.557 | BI16: 103 | BJ16: 92 | BK16: 29.355 | BL16: -1.893 | BM16: -2 | BN16: 66 | BO16: 0.89 | BP16: 192 | BQ16: 2.5 | BR16: 0.0028 | BS16: 1.736 | BT16: 0.43 | BU16: 14 | BV16: 1032 | BW16: 0.032 | BX16: 862 | BY16: 1.32 | BZ16: 4.6 | CA16: 0.40514 | CB16: 0.91 | CC16: 0.8 | CD16: 2.42 | CE16: 3051 | CF16: 4411 | CG16: 2.39 | CH16: 64.43485 | CI16: 1 | CJ16: 4.667 | CK16: 6 | CL16: 4 | CM16: 29.58 | CN16: 0.391 | CO16: 1 | CP16: 203 | CQ16: 2.376 | CR16: 87 | CS16: 1.5 | CT16: 2.1 | CU16: 7.572 | CV16: 0.278 | CW16: 14 | CX16: 1153 | CY16: 0.068 | CZ16: 971 | DA16: 1.07 | DB16: 3.73 | DC16: 0.23831 | DD16: 1.01 | DE16: 0.89 | DF16: 2.85 | DG16: 4562 | DH16: 6912 | DI16: 2.64 | DJ16: 51.12083 | DK16: 1 | DL16: 26.451 | DM16: 7 | DN16: 5 | DO16: 28.24 | DP16: 2.216 | DQ16: 1 | DR16: 154 | DS16: 1.911 | DT16: 83 | DU16: 1.5 | DV16: 0.53 | DW16: 3.926 | DX16: 1.8 | DY16: 12 | DZ16: 1653 | EA16: 0.116 | EB16: 2540 | EC16: 1.39 | ED16: 2.92 | EE16: 0.45404 | EF16: 0.99 | EG16: 1.13 | EH16: 2 | EI16: 1064 | EJ16: 4207 | EK16: 8.2 | EL16: 52.335 | EM16: 2 | EN16: 4.333 | EO16: 11 | EP16: 10 | EQ16: 26.4 | ER16: 1.089 | ES16: 2 | ET16: 192 | EU16: 2.151 | EV16: 92 | EW16: 4.5 | EX16: 1.2 | EY16: 5.632 | EZ16: 8.7258256 | FB16: =EZ16 -> 8.7258256 | FD16: -1816.7239 | FE16: =FD16/M16 -> -7.5696827 | FF16: =FE16*1000 -> -7569.6827 | FG16: 4.03132 | FH16: 4.03152 | FI16: 4.1227433 | FJ16: 67.00429 | FK16: =FJ16/M16 -> 0.27918454 | FL16: =FJ16 -> 67.00429 | FN16: -1.09 | FO16: 2.01 | FP16: 3.1 | FQ16: =FP16+0.01 -> 3.11 | FR16: =FQ16-2.86 -> 0.25 | FS16: =IF(FR16<0,0,1) -> 1
A17: K24 Na24 Sr1 Nb48 O143 | B17: Nb | C17: 48 | D17: O | E17: 143 | F17: K | G17: 24 | H17: Na | I17: 24 | J17: Sr | K17: 1 | M17: =C17+E17+G17+I17+K17 -> 240 | P17: 1.92 | Q17: 14 | R17: 3573 | S17: 1.702 | T17: 8570 | U17: 0.95 | V17: 1.75 | W17: 0.19256 | X17: 1.23 | Y17: 2.03 | Z17: 4 | AA17: 1382 | AB17: 2416 | AC17: 26.8 | AD17: 36.28 | AE17: 5 | AF17: 24.442 | AG17: 58 | AH17: 50 | AI17: 24.48 | AJ17: 6.144 | AK17: 3 | AL17: 134 | AM17: 1.468 | AN17: 450 | AO17: 4.5 | AP17: 1.15 | AQ17: 1.807 | AR17: 0.232 | AS17: 1 | AT17: 90.19 | AU17: 0.011 | AV17: 2000 | AW17: 0.85 | AX17: 1.2 | AY17: 0.82902 | AZ17: 3.5 | BA17: 3.32 | BB17: 7.54 | BC17: 3388 | BD17: 5300 | BE17: 0.444 | BF17: 205.19507 | BG17: 6 | BH17: 13.557 | BI17: 103 | BJ17: 92 | BK17: 29.355 | BL17: -1.893 | BM17: -2 | BN17: 66 | BO17: 0.89 | BP17: 192 | BQ17: 2.5 | BR17: 0.0028 | BS17: 1.736 | BT17: 0.43 | BU17: 14 | BV17: 1032 | BW17: 0.032 | BX17: 862 | BY17: 1.32 | BZ17: 4.6 | CA17: 0.40514 | CB17: 0.91 | CC17: 0.8 | CD17: 2.42 | CE17: 3051 | CF17: 4411 | CG17: 2.39 | CH17: 64.43485 | CI17: 1 | CJ17: 4.667 | CK17: 6 | CL17: 4 | CM17: 29.58 | CN17: 0.391 | CO17: 1 | CP17: 203 | CQ17: 2.376 | CR17: 87 | CS17: 1.5 | CT17: 2.1 | CU17: 7.572 | CV17: 0.278 | CW17: 14 | CX17: 1153 | CY17: 0.068 | CZ17: 971 | DA17: 1.07 | DB17: 3.73 | DC17: 0.23831 | DD17: 1.01 | DE17: 0.89 | DF17: 2.85 | DG17: 4562 | DH17: 6912 | DI17: 2.64 | DJ17: 51.12083 | DK17: 1 | DL17: 26.451 | DM17: 7 | DN17: 5 | DO17: 28.24 | DP17: 2.216 | DQ17: 1 | DR17: 154 | DS17: 1.911 | DT17: 83 | DU17: 1.5 | DV17: 0.53 | DW17: 3.926 | DX17: 1.8 | DY17: 12 | DZ17: 1653 | EA17: 0.116 | EB17: 2540 | EC17: 1.39 | ED17: 2.92 | EE17: 0.45404 | EF17: 0.99 | EG17: 1.13 | EH17: 2 | EI17: 1064 | EJ17: 4207 | EK17: 8.2 | EL17: 52.335 | EM17: 2 | EN17: 4.333 | EO17: 11 | EP17: 10 | EQ17: 26.4 | ER17: 1.089 | ES17: 2 | ET17: 192 | EU17: 2.151 | EV17: 92 | EW17: 4.5 | EX17: 1.2 | EY17: 5.632 | EZ17: 6.5153436 | FB17: =EZ17 -> 6.5153436 | FD17: -1824.0787 | FE17: =FD17/M17 -> -7.6003281 | FF17: =FE17*1000 -> -7600.3281 | FG17: 4.0340875 | FH17: 4.03279 | FI17: 4.11973 | FJ17: 67.022332 | FK17: =FJ17/M17 -> 0.27925972 | FL17: =FJ17 -> 67.022332 | FN17: -0.96 | FO17: 2.07 | FP17: 3.03 | FQ17: =FP17+0.01 -> 3.04 | FR17: =FQ17-2.86 -> 0.18 | FS17: =IF(FR17<0,0,1) -> 1
A18: K22 Na24 Sr1 Nb48 O144 | B18: Nb | C18: 48 | D18: O | E18: 144 | F18: K | G18: 22 | H18: Na | I18: 24 | J18: Sr | K18: 1 | M18: =C18+E18+G18+I18+K18 -> 239 | P18: 1.92 | Q18: 14 | R18: 3573 | S18: 1.702 | T18: 8570 | U18: 0.95 | V18: 1.75 | W18: 0.19256 | X18: 1.23 | Y18: 2.03 | Z18: 4 | AA18: 1382 | AB18: 2416 | AC18: 26.8 | AD18: 36.28 | AE18: 5 | AF18: 24.442 | AG18: 58 | AH18: 50 | AI18: 24.48 | AJ18: 6.144 | AK18: 3 | AL18: 134 | AM18: 1.468 | AN18: 450 | AO18: 4.5 | AP18: 1.15 | AQ18: 1.807 | AR18: 0.232 | AS18: 1 | AT18: 90.19 | AU18: 0.011 | AV18: 2000 | AW18: 0.85 | AX18: 1.2 | AY18: 0.82902 | AZ18: 3.5 | BA18: 3.32 | BB18: 7.54 | BC18: 3388 | BD18: 5300 | BE18: 0.444 | BF18: 205.19507 | BG18: 6 | BH18: 13.557 | BI18: 103 | BJ18: 92 | BK18: 29.355 | BL18: -1.893 | BM18: -2 | BN18: 66 | BO18: 0.89 | BP18: 192 | BQ18: 2.5 | BR18: 0.0028 | BS18: 1.736 | BT18: 0.43 | BU18: 14 | BV18: 1032 | BW18: 0.032 | BX18: 862 | BY18: 1.32 | BZ18: 4.6 | CA18: 0.40514 | CB18: 0.91 | CC18: 0.8 | CD18: 2.42 | CE18: 3051 | CF18: 4411 | CG18: 2.39 | CH18: 64.43485 | CI18: 1 | CJ18: 4.667 | CK18: 6 | CL18: 4 | CM18: 29.58 | CN18: 0.391 | CO18: 1 | CP18: 203 | CQ18: 2.376 | CR18: 87 | CS18: 1.5 | CT18: 2.1 | CU18: 7.572 | CV18: 0.278 | CW18: 14 | CX18: 1153 | CY18: 0.068 | CZ18: 971 | DA18: 1.07 | DB18: 3.73 | DC18: 0.23831 | DD18: 1.01 | DE18: 0.89 | DF18: 2.85 | DG18: 4562 | DH18: 6912 | DI18: 2.64 | DJ18: 51.12083 | DK18: 1 | DL18: 26.451 | DM18: 7 | DN18: 5 | DO18: 28.24 | DP18: 2.216 | DQ18: 1 | DR18: 154 | DS18: 1.911 | DT18: 83 | DU18: 1.5 | DV18: 0.53 | DW18: 3.926 | DX18: 1.8 | DY18: 12 | DZ18: 1653 | EA18: 0.116 | EB18: 2540 | EC18: 1.39 | ED18: 2.92 | EE18: 0.45404 | EF18: 0.99 | EG18: 1.13 | EH18: 2 | EI18: 1064 | EJ18: 4207 | EK18: 8.2 | EL18: 52.335 | EM18: 2 | EN18: 4.333 | EO18: 11 | EP18: 10 | EQ18: 26.4 | ER18: 1.089 | ES18: 2 | ET18: 192 | EU18: 2.151 | EV18: 92 | EW18: 4.5 | EX18: 1.2 | EY18: 5.632 | EZ18: 1.5744797 | FA18: 0.03280166 | FC18: =EZ18 -> 1.5744797 | FD18: -1833.2645 | FE18: =FD18/M18 -> -7.6705628 | FF18: =FE18*1000 -> -7670.5628 | FG18: 4.0068175 | FH18: 4.0066625 | FI18: 4.1260467 | FJ18: 66.239347 | FK18: =FJ18/M18 -> 0.27715208 | FM18: =FJ18 -> 66.239347 | FN18: -0.94 | FO18: 2.04 | FP18: 2.98 | FQ18: =FP18+0.01 -> 2.99 | FR18: =FQ18-2.86 -> 0.13 | FS18: =IF(FR18<0,0,1) -> 1
A19: K23 Na23 Sr1 Nb48 O144 | B19: Nb | C19: 48 | D19: O | E19: 144 | F19: K | G19: 23 | H19: Na | I19: 23 | J19: Sr | K19: 1 | M19: =C19+E19+G19+I19+K19 -> 239 | P19: 1.92 | Q19: 14 | R19: 3573 | S19: 1.702 | T19: 8570 | U19: 0.95 | V19: 1.75 | W19: 0.19256 | X19: 1.23 | Y19: 2.03 | Z19: 4 | AA19: 1382 | AB19: 2416 | AC19: 26.8 | AD19: 36.28 | AE19: 5 | AF19: 24.442 | AG19: 58 | AH19: 50 | AI19: 24.48 | AJ19: 6.144 | AK19: 3 | AL19: 134 | AM19: 1.468 | AN19: 450 | AO19: 4.5 | AP19: 1.15 | AQ19: 1.807 | AR19: 0.232 | AS19: 1 | AT19: 90.19 | AU19: 0.011 | AV19: 2000 | AW19: 0.85 | AX19: 1.2 | AY19: 0.82902 | AZ19: 3.5 | BA19: 3.32 | BB19: 7.54 | BC19: 3388 | BD19: 5300 | BE19: 0.444 | BF19: 205.19507 | BG19: 6 | BH19: 13.557 | BI19: 103 | BJ19: 92 | BK19: 29.355 | BL19: -1.893 | BM19: -2 | BN19: 66 | BO19: 0.89 | BP19: 192 | BQ19: 2.5 | BR19: 0.0028 | BS19: 1.736 | BT19: 0.43 | BU19: 14 | BV19: 1032 | BW19: 0.032 | BX19: 862 | BY19: 1.32 | BZ19: 4.6 | CA19: 0.40514 | CB19: 0.91 | CC19: 0.8 | CD19: 2.42 | CE19: 3051 | CF19: 4411 | CG19: 2.39 | CH19: 64.43485 | CI19: 1 | CJ19: 4.667 | CK19: 6 | CL19: 4 | CM19: 29.58 | CN19: 0.391 | CO19: 1 | CP19: 203 | CQ19: 2.376 | CR19: 87 | CS19: 1.5 | CT19: 2.1 | CU19: 7.572 | CV19: 0.278 | CW19: 14 | CX19: 1153 | CY19: 0.068 | CZ19: 971 | DA19: 1.07 | DB19: 3.73 | DC19: 0.23831 | DD19: 1.01 | DE19: 0.89 | DF19: 2.85 | DG19: 4562 | DH19: 6912 | DI19: 2.64 | DJ19: 51.12083 | DK19: 1 | DL19: 26.451 | DM19: 7 | DN19: 5 | DO19: 28.24 | DP19: 2.216 | DQ19: 1 | DR19: 154 | DS19: 1.911 | DT19: 83 | DU19: 1.5 | DV19: 0.53 | DW19: 3.926 | DX19: 1.8 | DY19: 12 | DZ19: 1653 | EA19: 0.116 | EB19: 2540 | EC19: 1.39 | ED19: 2.92 | EE19: 0.45404 | EF19: 0.99 | EG19: 1.13 | EH19: 2 | EI19: 1064 | EJ19: 4207 | EK19: 8.2 | EL19: 52.335 | EM19: 2 | EN19: 4.333 | EO19: 11 | EP19: 10 | EQ19: 26.4 | ER19: 1.089 | ES19: 2 | ET19: 192 | EU19: 2.151 | EV19: 92 | EW19: 4.5 | EX19: 1.2 | EY19: 5.632 | EZ19: 1.3216785 | FA19: 0.02753497 | FC19: =EZ19 -> 1.3216785 | FD19: -1833.2331 | FE19: =FD19/M19 -> -7.6704313 | FF19: =FE19*1000 -> -7670.4313 | FG19: 4.00691 | FH19: 4.0063775 | FI19: 4.1384233 | FJ19: 66.434918 | FK19: =FJ19/M19 -> 0.27797037 | FM19: =FJ19 -> 66.434918 | FN19: -0.95 | FO19: 2.06 | FP19: 3.01 | FQ19: =FP19+0.01 -> 3.02 | FR19: =FQ19-2.86 -> 0.16 | FS19: =IF(FR19<0,0,1) -> 1
A20: K23 Na24 Sr1 Nb47 O144 | B20: Nb | C20: 47 | D20: O | E20: 144 | F20: K | G20: 23 | H20: Na | I20: 24 | J20: Sr | K20: 1 | M20: =C20+E20+G20+I20+K20 -> 239 | P20: 1.92 | Q20: 14 | R20: 3573 | S20: 1.702 | T20: 8570 | U20: 0.95 | V20: 1.75 | W20: 0.19256 | X20: 1.23 | Y20: 2.03 | Z20: 4 | AA20: 1382 | AB20: 2416 | AC20: 26.8 | AD20: 36.28 | AE20: 5 | AF20: 24.442 | AG20: 58 | AH20: 50 | AI20: 24.48 | AJ20: 6.144 | AK20: 3 | AL20: 134 | AM20: 1.468 | AN20: 450 | AO20: 4.5 | AP20: 1.15 | AQ20: 1.807 | AR20: 0.232 | AS20: 1 | AT20: 90.19 | AU20: 0.011 | AV20: 2000 | AW20: 0.85 | AX20: 1.2 | AY20: 0.82902 | AZ20: 3.5 | BA20: 3.32 | BB20: 7.54 | BC20: 3388 | BD20: 5300 | BE20: 0.444 | BF20: 205.19507 | BG20: 6 | BH20: 13.557 | BI20: 103 | BJ20: 92 | BK20: 29.355 | BL20: -1.893 | BM20: -2 | BN20: 66 | BO20: 0.89 | BP20: 192 | BQ20: 2.5 | BR20: 0.0028 | BS20: 1.736 | BT20: 0.43 | BU20: 14 | BV20: 1032 | BW20: 0.032 | BX20: 862 | BY20: 1.32 | BZ20: 4.6 | CA20: 0.40514 | CB20: 0.91 | CC20: 0.8 | CD20: 2.42 | CE20: 3051 | CF20: 4411 | CG20: 2.39 | CH20: 64.43485 | CI20: 1 | CJ20: 4.667 | CK20: 6 | CL20: 4 | CM20: 29.58 | CN20: 0.391 | CO20: 1 | CP20: 203 | CQ20: 2.376 | CR20: 87 | CS20: 1.5 | CT20: 2.1 | CU20: 7.572 | CV20: 0.278 | CW20: 14 | CX20: 1153 | CY20: 0.068 | CZ20: 971 | DA20: 1.07 | DB20: 3.73 | DC20: 0.23831 | DD20: 1.01 | DE20: 0.89 | DF20: 2.85 | DG20: 4562 | DH20: 6912 | DI20: 2.64 | DJ20: 51.12083 | DK20: 1 | DL20: 26.451 | DM20: 7 | DN20: 5 | DO20: 28.24 | DP20: 2.216 | DQ20: 1 | DR20: 154 | DS20: 1.911 | DT20: 83 | DU20: 1.5 | DV20: 0.53 | DW20: 3.926 | DX20: 1.8 | DY20: 12 | DZ20: 1653 | EA20: 0.116 | EB20: 2540 | EC20: 1.39 | ED20: 2.92 | EE20: 0.45404 | EF20: 0.99 | EG20: 1.13 | EH20: 2 | EI20: 1064 | EJ20: 4207 | EK20: 8.2 | EL20: 52.335 | EM20: 2 | EN20: 4.333 | EO20: 11 | EP20: 10 | EQ20: 26.4 | ER20: 1.089 | ES20: 2 | ET20: 192 | EU20: 2.151 | EV20: 92 | EW20: 4.5 | EX20: 1.2 | EY20: 5.632 | EZ20: 12.66727 | FA20: 0.26390145 | FC20: =EZ20 -> 12.66727 | FD20: -1813.1059 | FE20: =FD20/M20 -> -7.5862172 | FF20: =FE20*1000 -> -7586.2172 | FG20: 4.00535 | FH20: 4.0055625 | FI20: 4.1329767 | FJ20: 66.308161 | FK20: =FJ20/M20 -> 0.27744 | FM20: =FJ20 -> 66.308161 | FN20: -1.13 | FO20: 2.21 | FP20: 3.34 | FQ20: =FP20+0.01 -> 3.35 | FR20: =FQ20-2.86 -> 0.49 | FS20: =IF(FR20<0,0,1) -> 1
A21: K23 Na24 Sr1 Nb48 O143 | B21: Nb | C21: 48 | D21: O | E21: 143 | F21: K | G21: 23 | H21: Na | I21: 24 | J21: Sr | K21: 1 | M21: =C21+E21+G21+I21+K21 -> 239 | P21: 1.92 | Q21: 14 | R21: 3573 | S21: 1.702 | T21: 8570 | U21: 0.95 | V21: 1.75 | W21: 0.19256 | X21: 1.23 | Y21: 2.03 | Z21: 4 | AA21: 1382 | AB21: 2416 | AC21: 26.8 | AD21: 36.28 | AE21: 5 | AF21: 24.442 | AG21: 58 | AH21: 50 | AI21: 24.48 | AJ21: 6.144 | AK21: 3 | AL21: 134 | AM21: 1.468 | AN21: 450 | AO21: 4.5 | AP21: 1.15 | AQ21: 1.807 | AR21: 0.232 | AS21: 1 | AT21: 90.19 | AU21: 0.011 | AV21: 2000 | AW21: 0.85 | AX21: 1.2 | AY21: 0.82902 | AZ21: 3.5 | BA21: 3.32 | BB21: 7.54 | BC21: 3388 | BD21: 5300 | BE21: 0.444 | BF21: 205.19507 | BG21: 6 | BH21: 13.557 | BI21: 103 | BJ21: 92 | BK21: 29.355 | BL21: -1.893 | BM21: -2 | BN21: 66 | BO21: 0.89 | BP21: 192 | BQ21: 2.5 | BR21: 0.0028 | BS21: 1.736 | BT21: 0.43 | BU21: 14 | BV21: 1032 | BW21: 0.032 | BX21: 862 | BY21: 1.32 | BZ21: 4.6 | CA21: 0.40514 | CB21: 0.91 | CC21: 0.8 | CD21: 2.42 | CE21: 3051 | CF21: 4411 | CG21: 2.39 | CH21: 64.43485 | CI21: 1 | CJ21: 4.667 | CK21: 6 | CL21: 4 | CM21: 29.58 | CN21: 0.391 | CO21: 1 | CP21: 203 | CQ21: 2.376 | CR21: 87 | CS21: 1.5 | CT21: 2.1 | CU21: 7.572 | CV21: 0.278 | CW21: 14 | CX21: 1153 | CY21: 0.068 | CZ21: 971 | DA21: 1.07 | DB21: 3.73 | DC21: 0.23831 | DD21: 1.01 | DE21: 0.89 | DF21: 2.85 | DG21: 4562 | DH21: 6912 | DI21: 2.64 | DJ21: 51.12083 | DK21: 1 | DL21: 26.451 | DM21: 7 | DN21: 5 | DO21: 28.24 | DP21: 2.216 | DQ21: 1 | DR21: 154 | DS21: 1.911 | DT21: 83 | DU21: 1.5 | DV21: 0.53 | DW21: 3.926 | DX21: 1.8 | DY21: 12 | DZ21: 1653 | EA21: 0.116 | EB21: 2540 | EC21: 1.39 | ED21: 2.92 | EE21: 0.45404 | EF21: 0.99 | EG21: 1.13 | EH21: 2 | EI21: 1064 | EJ21: 4207 | EK21: 8.2 | EL21: 52.335 | EM21: 2 | EN21: 4.333 | EO21: 11 | EP21: 10 | EQ21: 26.4 | ER21: 1.089 | ES21: 2 | ET21: 192 | EU21: 2.151 | EV21: 92 | EW21: 4.5 | EX21: 1.2 | EY21: 5.632 | EZ21: 3.2692766 | FA21: 0.068109928 | FC21: =EZ21 -> 3.2692766 | FD21: -1827.6483 | FE21: =FD21/M21 -> -7.647064 | FF21: =FE21*1000 -> -7647.064 | FG21: 4.008095 | FH21: 4.010075 | FI21: 4.12466 | FJ21: 66.294686 | FK21: =FJ21/M21 -> 0.27738363 | FM21: =FJ21 -> 66.294686 | FN21: -0.96 | FO21: 2.17 | FP21: 3.13 | FQ21: =FP21+0.01 -> 3.14 | FR21: =FQ21-2.86 -> 0.28 | FS21: =IF(FR21<0,0,1) -> 1
A22: K23 Na23 Sr1 Nb48 O144 | B22: Nb | C22: 48 | D22: O | E22: 144 | F22: K | G22: 23 | H22: Na | I22: 23 | J22: Sr | K22: 1 | M22: =C22+E22+G22+I22+K22 -> 239 | P22: 1.92 | Q22: 14 | R22: 3573 | S22: 1.702 | T22: 8570 | U22: 0.95 | V22: 1.75 | W22: 0.19256 | X22: 1.23 | Y22: 2.03 | Z22: 4 | AA22: 1382 | AB22: 2416 | AC22: 26.8 | AD22: 36.28 | AE22: 5 | AF22: 24.442 | AG22: 58 | AH22: 50 | AI22: 24.48 | AJ22: 6.144 | AK22: 3 | AL22: 134 | AM22: 1.468 | AN22: 450 | AO22: 4.5 | AP22: 1.15 | AQ22: 1.807 | AR22: 0.232 | AS22: 1 | AT22: 90.19 | AU22: 0.011 | AV22: 2000 | AW22: 0.85 | AX22: 1.2 | AY22: 0.82902 | AZ22: 3.5 | BA22: 3.32 | BB22: 7.54 | BC22: 3388 | BD22: 5300 | BE22: 0.444 | BF22: 205.19507 | BG22: 6 | BH22: 13.557 | BI22: 103 | BJ22: 92 | BK22: 29.355 | BL22: -1.893 | BM22: -2 | BN22: 66 | BO22: 0.89 | BP22: 192 | BQ22: 2.5 | BR22: 0.0028 | BS22: 1.736 | BT22: 0.43 | BU22: 14 | BV22: 1032 | BW22: 0.032 | BX22: 862 | BY22: 1.32 | BZ22: 4.6 | CA22: 0.40514 | CB22: 0.91 | CC22: 0.8 | CD22: 2.42 | CE22: 3051 | CF22: 4411 | CG22: 2.39 | CH22: 64.43485 | CI22: 1 | CJ22: 4.667 | CK22: 6 | CL22: 4 | CM22: 29.58 | CN22: 0.391 | CO22: 1 | CP22: 203 | CQ22: 2.376 | CR22: 87 | CS22: 1.5 | CT22: 2.1 | CU22: 7.572 | CV22: 0.278 | CW22: 14 | CX22: 1153 | CY22: 0.068 | CZ22: 971 | DA22: 1.07 | DB22: 3.73 | DC22: 0.23831 | DD22: 1.01 | DE22: 0.89 | DF22: 2.85 | DG22: 4562 | DH22: 6912 | DI22: 2.64 | DJ22: 51.12083 | DK22: 1 | DL22: 26.451 | DM22: 7 | DN22: 5 | DO22: 28.24 | DP22: 2.216 | DQ22: 1 | DR22: 154 | DS22: 1.911 | DT22: 83 | DU22: 1.5 | DV22: 0.53 | DW22: 3.926 | DX22: 1.8 | DY22: 12 | DZ22: 1653 | EA22: 0.116 | EB22: 2540 | EC22: 1.39 | ED22: 2.92 | EE22: 0.45404 | EF22: 0.99 | EG22: 1.13 | EH22: 2 | EI22: 1064 | EJ22: 4207 | EK22: 8.2 | EL22: 52.335 | EM22: 2 | EN22: 4.333 | EO22: 11 | EP22: 10 | EQ22: 26.4 | ER22: 1.089 | ES22: 2 | ET22: 192 | EU22: 2.151 | EV22: 92 | EW22: 4.5 | EX22: 1.2 | EY22: 5.632 | EZ22: 1.8072797 | FA22: 0.03765166 | FC22: =EZ22 -> 1.8072797 | FD22: -1832.9948 | FE22: =FD22/M22 -> -7.6694344 | FF22: =FE22*1000 -> -7669.4344 | FG22: 4.00549 | FH22: 4.0049425 | FI22: 4.14037 | FJ22: 66.418784 | FK22: =FJ22/M22 -> 0.27790286 | FM22: =FJ22 -> 66.418784 | FN22: -0.99 | FO22: 2.13 | FP22: 3.12 | FQ22: =FP22+0.01 -> 3.13 | FR22: =FQ22-2.86 -> 0.27 | FS22: =IF(FR22<0,0,1) -> 1
A23: K24 Na22 Sr1 Nb48 O144 | B23: Nb | C23: 48 | D23: O | E23: 144 | F23: K | G23: 24 | H23: Na | I23: 22 | J23: Sr | K23: 1 | M23: =C23+E23+G23+I23+K23 -> 239 | P23: 1.92 | Q23: 14 | R23: 3573 | S23: 1.702 | T23: 8570 | U23: 0.95 | V23: 1.75 | W23: 0.19256 | X23: 1.23 | Y23: 2.03 | Z23: 4 | AA23: 1382 | AB23: 2416 | AC23: 26.8 | AD23: 36.28 | AE23: 5 | AF23: 24.442 | AG23: 58 | AH23: 50 | AI23: 24.48 | AJ23: 6.144 | AK23: 3 | AL23: 134 | AM23: 1.468 | AN23: 450 | AO23: 4.5 | AP23: 1.15 | AQ23: 1.807 | AR23: 0.232 | AS23: 1 | AT23: 90.19 | AU23: 0.011 | AV23: 2000 | AW23: 0.85 | AX23: 1.2 | AY23: 0.82902 | AZ23: 3.5 | BA23: 3.32 | BB23: 7.54 | BC23: 3388 | BD23: 5300 | BE23: 0.444 | BF23: 205.19507 | BG23: 6 | BH23: 13.557 | BI23: 103 | BJ23: 92 | BK23: 29.355 | BL23: -1.893 | BM23: -2 | BN23: 66 | BO23: 0.89 | BP23: 192 | BQ23: 2.5 | BR23: 0.0028 | BS23: 1.736 | BT23: 0.43 | BU23: 14 | BV23: 1032 | BW23: 0.032 | BX23: 862 | BY23: 1.32 | BZ23: 4.6 | CA23: 0.40514 | CB23: 0.91 | CC23: 0.8 | CD23: 2.42 | CE23: 3051 | CF23: 4411 | CG23: 2.39 | CH23: 64.43485 | CI23: 1 | CJ23: 4.667 | CK23: 6 | CL23: 4 | CM23: 29.58 | CN23: 0.391 | CO23: 1 | CP23: 203 | CQ23: 2.376 | CR23: 87 | CS23: 1.5 | CT23: 2.1 | CU23: 7.572 | CV23: 0.278 | CW23: 14 | CX23: 1153 | CY23: 0.068 | CZ23: 971 | DA23: 1.07 | DB23: 3.73 | DC23: 0.23831 | DD23: 1.01 | DE23: 0.89 | DF23: 2.85 | DG23: 4562 | DH23: 6912 | DI23: 2.64 | DJ23: 51.12083 | DK23: 1 | DL23: 26.451 | DM23: 7 | DN23: 5 | DO23: 28.24 | DP23: 2.216 | DQ23: 1 | DR23: 154 | DS23: 1.911 | DT23: 83 | DU23: 1.5 | DV23: 0.53 | DW23: 3.926 | DX23: 1.8 | DY23: 12 | DZ23: 1653 | EA23: 0.116 | EB23: 2540 | EC23: 1.39 | ED23: 2.92 | EE23: 0.45404 | EF23: 0.99 | EG23: 1.13 | EH23: 2 | EI23: 1064 | EJ23: 4207 | EK23: 8.2 | EL23: 52.335 | EM23: 2 | EN23: 4.333 | EO23: 11 | EP23: 10 | EQ23: 26.4 | ER23: 1.089 | ES23: 2 | ET23: 192 | EU23: 2.151 | EV23: 92 | EW23: 4.5 | EX23: 1.2 | EY23: 5.632 | EZ23: 1.4195546 | FA23: 0.029574053 | FC23: =EZ23 -> 1.4195546 | FD23: -1833.0983 | FE23: =FD23/M23 -> -7.6698675 | FF23: =FE23*1000 -> -7669.8675 | FG23: 4.00643 | FH23: 4.00631 | FI23: 4.16878 | FJ23: 66.913085 | FK23: =FJ23/M23 -> 0.27997107 | FM23: =FJ23 -> 66.913085 | FN23: -1.01 | FO23: 2 | FP23: 3.01 | FQ23: =FP23+0.01 -> 3.02 | FR23: =FQ23-2.86 -> 0.16 | FS23: =IF(FR23<0,0,1) -> 1
A24: K24 Na23 Sr1 Nb47 O144 | B24: Nb | C24: 47 | D24: O | E24: 144 | F24: K | G24: 24 | H24: Na | I24: 23 | J24: Sr | K24: 1 | M24: =C24+E24+G24+I24+K24 -> 239 | P24: 1.92 | Q24: 14 | R24: 3573 | S24: 1.702 | T24: 8570 | U24: 0.95 | V24: 1.75 | W24: 0.19256 | X24: 1.23 | Y24: 2.03 | Z24: 4 | AA24: 1382 | AB24: 2416 | AC24: 26.8 | AD24: 36.28 | AE24: 5 | AF24: 24.442 | AG24: 58 | AH24: 50 | AI24: 24.48 | AJ24: 6.144 | AK24: 3 | AL24: 134 | AM24: 1.468 | AN24: 450 | AO24: 4.5 | AP24: 1.15 | AQ24: 1.807 | AR24: 0.232 | AS24: 1 | AT24: 90.19 | AU24: 0.011 | AV24: 2000 | AW24: 0.85 | AX24: 1.2 | AY24: 0.82902 | AZ24: 3.5 | BA24: 3.32 | BB24: 7.54 | BC24: 3388 | BD24: 5300 | BE24: 0.444 | BF24: 205.19507 | BG24: 6 | BH24: 13.557 | BI24: 103 | BJ24: 92 | BK24: 29.355 | BL24: -1.893 | BM24: -2 | BN24: 66 | BO24: 0.89 | BP24: 192 | BQ24: 2.5 | BR24: 0.0028 | BS24: 1.736 | BT24: 0.43 | BU24: 14 | BV24: 1032 | BW24: 0.032 | BX24: 862 | BY24: 1.32 | BZ24: 4.6 | CA24: 0.40514 | CB24: 0.91 | CC24: 0.8 | CD24: 2.42 | CE24: 3051 | CF24: 4411 | CG24: 2.39 | CH24: 64.43485 | CI24: 1 | CJ24: 4.667 | CK24: 6 | CL24: 4 | CM24: 29.58 | CN24: 0.391 | CO24: 1 | CP24: 203 | CQ24: 2.376 | CR24: 87 | CS24: 1.5 | CT24: 2.1 | CU24: 7.572 | CV24: 0.278 | CW24: 14 | CX24: 1153 | CY24: 0.068 | CZ24: 971 | DA24: 1.07 | DB24: 3.73 | DC24: 0.23831 | DD24: 1.01 | DE24: 0.89 | DF24: 2.85 | DG24: 4562 | DH24: 6912 | DI24: 2.64 | DJ24: 51.12083 | DK24: 1 | DL24: 26.451 | DM24: 7 | DN24: 5 | DO24: 28.24 | DP24: 2.216 | DQ24: 1 | DR24: 154 | DS24: 1.911 | DT24: 83 | DU24: 1.5 | DV24: 0.53 | DW24: 3.926 | DX24: 1.8 | DY24: 12 | DZ24: 1653 | EA24: 0.116 | EB24: 2540 | EC24: 1.39 | ED24: 2.92 | EE24: 0.45404 | EF24: 0.99 | EG24: 1.13 | EH24: 2 | EI24: 1064 | EJ24: 4207 | EK24: 8.2 | EL24: 52.335 | EM24: 2 | EN24: 4.333 | EO24: 11 | EP24: 10 | EQ24: 26.4 | ER24: 1.089 | ES24: 2 | ET24: 192 | EU24: 2.151 | EV24: 92 | EW24: 4.5 | EX24: 1.2 | EY24: 5.632 | EZ24: 13.762687 | FA24: 0.28672264 | FC24: =EZ24 -> 13.762687 | FD24: -1811.9736 | FE24: =FD24/M24 -> -7.5814796 | FF24: =FE24*1000 -> -7581.4796 | FG24: 4.00962 | FH24: 4.010485 | FI24: 4.1245933 | FJ24: 66.325559 | FK24: =FJ24/M24 -> 0.2775128 | FM24: =FJ24 -> 66.325559 | FN24: -1.07 | FO24: 1.9 | FP24: 2.97 | FQ24: =FP24+0.01 -> 2.98 | FR24: =FQ24-2.86 -> 0.12 | FS24: =IF(FR24<0,0,1) -> 1
A25: K24 Na23 Sr1 Nb48 O143 | B25: Nb | C25: 48 | D25: O | E25: 143 | F25: K | G25: 24 | H25: Na | I25: 23 | J25: Sr | K25: 1 | M25: =C25+E25+G25+I25+K25 -> 239 | P25: 1.92 | Q25: 14 | R25: 3573 | S25: 1.702 | T25: 8570 | U25: 0.95 | V25: 1.75 | W25: 0.19256 | X25: 1.23 | Y25: 2.03 | Z25: 4 | AA25: 1382 | AB25: 2416 | AC25: 26.8 | AD25: 36.28 | AE25: 5 | AF25: 24.442 | AG25: 58 | AH25: 50 | AI25: 24.48 | AJ25: 6.144 | AK25: 3 | AL25: 134 | AM25: 1.468 | AN25: 450 | AO25: 4.5 | AP25: 1.15 | AQ25: 1.807 | AR25: 0.232 | AS25: 1 | AT25: 90.19 | AU25: 0.011 | AV25: 2000 | AW25: 0.85 | AX25: 1.2 | AY25: 0.82902 | AZ25: 3.5 | BA25: 3.32 | BB25: 7.54 | BC25: 3388 | BD25: 5300 | BE25: 0.444 | BF25: 205.19507 | BG25: 6 | BH25: 13.557 | BI25: 103 | BJ25: 92 | BK25: 29.355 | BL25: -1.893 | BM25: -2 | BN25: 66 | BO25: 0.89 | BP25: 192 | BQ25: 2.5 | BR25: 0.0028 | BS25: 1.736 | BT25: 0.43 | BU25: 14 | BV25: 1032 | BW25: 0.032 | BX25: 862 | BY25: 1.32 | BZ25: 4.6 | CA25: 0.40514 | CB25: 0.91 | CC25: 0.8 | CD25: 2.42 | CE25: 3051 | CF25: 4411 | CG25: 2.39 | CH25: 64.43485 | CI25: 1 | CJ25: 4.667 | CK25: 6 | CL25: 4 | CM25: 29.58 | CN25: 0.391 | CO25: 1 | CP25: 203 | CQ25: 2.376 | CR25: 87 | CS25: 1.5 | CT25: 2.1 | CU25: 7.572 | CV25: 0.278 | CW25: 14 | CX25: 1153 | CY25: 0.068 | CZ25: 971 | DA25: 1.07 | DB25: 3.73 | DC25: 0.23831 | DD25: 1.01 | DE25: 0.89 | DF25: 2.85 | DG25: 4562 | DH25: 6912 | DI25: 2.64 | DJ25: 51.12083 | DK25: 1 | DL25: 26.451 | DM25: 7 | DN25: 5 | DO25: 28.24 | DP25: 2.216 | DQ25: 1 | DR25: 154 | DS25: 1.911 | DT25: 83 | DU25: 1.5 | DV25: 0.53 | DW25: 3.926 | DX25: 1.8 | DY25: 12 | DZ25: 1653 | EA25: 0.116 | EB25: 2540 | EC25: 1.39 | ED25: 2.92 | EE25: 0.45404 | EF25: 0.99 | EG25: 1.13 | EH25: 2 | EI25: 1064 | EJ25: 4207 | EK25: 8.2 | EL25: 52.335 | EM25: 2 | EN25: 4.333 | EO25: 11 | EP25: 10 | EQ25: 26.4 | ER25: 1.089 | ES25: 2 | ET25: 192 | EU25: 2.151 | EV25: 92 | EW25: 4.5 | EX25: 1.2 | EY25: 5.632 | EZ25: 4.6570796 | FA25: 0.097022491 | FC25: =EZ25 -> 4.6570796 | FD25: -1826.2236 | FE25: =FD25/M25 -> -7.641103 | FF25: =FE25*1000 -> -7641.103 | FG25: 4.00647 | FH25: 4.007005 | FI25: 4.1307133 | FJ25: 66.314218 | FK25: =FJ25/M25 -> 0.27746535 | FM25: =FJ25 -> 66.314218 | FN25: -0.92 | FO25: 2.18 | FP25: 3.1 | FQ25: =FP25+0.01 -> 3.11 | FR25: =FQ25-2.86 -> 0.25 | FS25: =IF(FR25<0,0,1) -> 1
A26: K23 Na24 Mg1 Nb48 O144 | B26: Nb | C26: 48 | D26: O | E26: 144 | F26: K | G26: 23 | H26: Na | I26: 24 | J26: Mg | K26: 1 | M26: =C26+E26+G26+I26+K26 -> 240 | P26: 1.92 | Q26: 14 | R26: 3573 | S26: 1.702 | T26: 8570 | U26: 0.95 | V26: 1.75 | W26: 0.19256 | X26: 1.23 | Y26: 2.03 | Z26: 4 | AA26: 1382 | AB26: 2416 | AC26: 26.8 | AD26: 36.28 | AE26: 5 | AF26: 24.442 | AG26: 58 | AH26: 50 | AI26: 24.48 | AJ26: 6.144 | AK26: 3 | AL26: 134 | AM26: 1.468 | AN26: 450 | AO26: 4.5 | AP26: 1.15 | AQ26: 1.807 | AR26: 0.232 | AS26: 1 | AT26: 90.19 | AU26: 0.011 | AV26: 2000 | AW26: 0.85 | AX26: 1.2 | AY26: 0.82902 | AZ26: 3.5 | BA26: 3.32 | BB26: 7.54 | BC26: 3388 | BD26: 5300 | BE26: 0.444 | BF26: 205.19507 | BG26: 6 | BH26: 13.557 | BI26: 103 | BJ26: 92 | BK26: 29.355 | BL26: -1.893 | BM26: -2 | BN26: 66 | BO26: 0.89 | BP26: 192 | BQ26: 2.5 | BR26: 0.0028 | BS26: 1.736 | BT26: 0.43 | BU26: 14 | BV26: 1032 | BW26: 0.032 | BX26: 862 | BY26: 1.32 | BZ26: 4.6 | CA26: 0.40514 | CB26: 0.91 | CC26: 0.8 | CD26: 2.42 | CE26: 3051 | CF26: 4411 | CG26: 2.39 | CH26: 64.43485 | CI26: 1 | CJ26: 4.667 | CK26: 6 | CL26: 4 | CM26: 29.58 | CN26: 0.391 | CO26: 1 | CP26: 203 | CQ26: 2.376 | CR26: 87 | CS26: 1.5 | CT26: 2.1 | CU26: 7.572 | CV26: 0.278 | CW26: 14 | CX26: 1153 | CY26: 0.068 | CZ26: 971 | DA26: 1.07 | DB26: 3.73 | DC26: 0.23831 | DD26: 1.01 | DE26: 0.89 | DF26: 2.85 | DG26: 4562 | DH26: 6912 | DI26: 2.64 | DJ26: 51.12083 | DK26: 1 | DL26: 26.451 | DM26: 7 | DN26: 5 | DO26: 28.24 | DP26: 2.216 | DQ26: 1 | DR26: 154 | DS26: 1.911 | DT26: 83 | DU26: 1.5 | DV26: 0.53 | DW26: 3.926 | DX26: 0.288 | DY26: 12 | DZ26: 1363 | EA26: 0.354 | EB26: 1738 | EC26: 1.09 | ED26: 2.3 | EE26: 0.12601 | EF26: 1.23 | EG26: 1.31 | EH26: 8.3 | EI26: 1451 | EJ26: 7733 | EK26: 8.9 | EL26: 32.69891 | EM26: 2 | EN26: 6.12 | EO26: 13 | EP26: 12 | EQ26: 24.869 | ER26: 0.855 | ES26: 2 | ET26: 136 | EU26: 1602 | EV26: 98 | EW26: 2.5 | EX26: 0.063 | EY26: 2.324 | EZ26: 1.3038605 | FB26: =EZ26 -> 1.3038605 | FD26: -1833.0862 | FE26: =FD26/M26 -> -7.6378592 | FF26: =FE26*1000 -> -7637.8592 | FG26: 4.0325175 | FH26: 4.031555 | FI26: 4.1186433 | FJ26: 66.958087 | FK26: =FJ26/M26 -> 0.27899203 | FL26: =FJ26 -> 66.958087 | FN26: -0.91 | FO26: 1.87 | FP26: 2.78 | FQ26: =FP26+0.01 -> 2.79 | FR26: =FQ26-2.86 -> -0.07 | FS26: =IF(FR26<0,0,1) -> 0
